Workbook

Sheet Languages Overview
A1: Priority | B1: Language | D1: 1 | E1: 2 | F1: 3a | G1: 3b | H1: 3c | I1: 4a | J1: 4b | K1: 5a | L1: 5b | M1: 5c | N1: 6a | O1: 6b | P1: 7a | Q1: 7b | R1: 8 | S1: 9a | T1: 9b | U1: 10 | V1: 11 | W1: 12 | X1: 13 | Y1: 14 | Z1: 15 | AA1: 16 | AB1: 17 | AC1: 18 | AD1: 19 | AE1: 20 | AF1: 21 | AG1: 22 | AH1: 23 | AI1: 24 | AJ1: 25 | AK1: 26 | AL1: 27 | AM1: 28 | AN1: 29 | AO1: 30 | AP1: 31 | AQ1: 32 | AR1: 33 | AS1: 34 | AT1: 35 | AU1: 36 | AV1: 37 | AW1: 38 | AX1: 39 | AY1: 40 | AZ1: 41 | BA1: 42 | BB1: 43 | BC1: 44 | BD1: 45 | BE1: 46 | BF1: 47 | BG1: 48 | BH1: 49 | BI1: 50 | BJ1: 51 | BK1: 52 | BL1: 53 | BM1: 54 | BN1: 55 | BO1: 56 | BP1: 57 | BQ1: 58 | BR1: 59 | BS1: 60 | BT1: 61 | BU1: 62 | BV1: 63 | BW1: 64 | BX1: 65 | BY1: 66 | BZ1: 67 | CA1: 68 | CB1: 69 | CC1: 70 | CD1: 71 | CE1: 72 | CF1: 73 | CG1: 74 | CH1: 75 | CI1: 76 | CJ1: 77 | CK1: 78 | CL1: 79 | CM1: 80 | CN1: 81 | CO1: 82 | CP1: 83 | CQ1: 84 | CR1: 85 | CS1: 86 | CT1: 87 | CU1: 88 | CV1: 89 | CW1: 90 | CX1: 91 | CY1: 92 | CZ1: 93 | DA1: 94 | DB1: 95 | DC1: 96 | DD1: 97 | DE1: 98 | DF1: 99 | DG1: 100 | DH1: 101 | DI1: 102 | DJ1: 103 | DK1: 104
B2: LATĪNUM | C2: LAT | D2: ='001 B-'!B10 -> 2 | E2: ='002 B-'!B10 -> 2 | F2: ='003 T-'!B10 -> 5 | G2: ='003 T-'!B10 -> 5 | H2: ='003 T-'!B10 -> 5 | I2: ='004 T-'!B10 -> 5 | J2: ='004 T-'!B10 -> 5 | K2: ='005 D-'!B10 -> 6 | L2: ='005 D-'!B10 -> 6 | M2: ='005 D-'!B10 -> 6 | N2: ='006 D-'!B10 -> 6 | O2: ='006 D-'!B10 -> 6 | P2: ='007 C-'!B10 -> 19 | Q2: ='007 C-'!B10 -> 19 | R2: ='008 C-'!B10 -> 19 | S2: ='009 C-'!B10 -> 19 | T2: ='009 C-'!B10 -> 19 | U2: ='001 B-'!B10 | V2: ='001 B-'!B10 | W2: ='001 B-'!B10 | X2: ='001 B-'!B10 | Y2: ='001 B-'!B10 | Z2: ='001 B-'!B10 | AA2: ='001 B-'!B10 | AB2: ='001 B-'!B10 | AC2: ='001 B-'!B10 | AD2: ='001 B-'!B10 | AE2: ='001 B-'!B10 | AF2: ='001 B-'!B10 | AG2: ='001 B-'!B10 | AH2: ='001 B-'!B10 | AI2: ='001 B-'!B10 | AJ2: ='001 B-'!B10 | AK2: ='001 B-'!B10 | AL2: ='001 B-'!B10 | AM2: ='001 B-'!B10 | AN2: ='001 B-'!B10 | AO2: ='001 B-'!B10 | AP2: ='001 B-'!B10 | AQ2: ='001 B-'!B10 | AR2: ='001 B-'!B10 | AS2: ='001 B-'!B10 | AT2: ='001 B-'!B10 | AU2: ='001 B-'!B10 | AV2: ='001 B-'!B10 | AW2: ='001 B-'!B10 | AX2: ='001 B-'!B10 | AY2: ='001 B-'!B10 | AZ2: ='001 B-'!B10 | BA2: ='001 B-'!B10 | BB2: ='001 B-'!B10 | BC2: ='001 B-'!B10 | BD2: ='001 B-'!B10 | BE2: ='001 B-'!B10 | BF2: ='001 B-'!B10 | BG2: ='001 B-'!B10 | BH2: ='001 B-'!B10 | BI2: ='001 B-'!B10 | BJ2: ='001 B-'!B10 | BK2: ='001 B-'!B10 | BL2: ='001 B-'!B10 | BM2: ='001 B-'!B10 | BN2: ='001 B-'!B10 | BO2: ='001 B-'!B10 | BP2: ='001 B-'!B10 | BQ2: ='001 B-'!B10 | BR2: ='001 B-'!B10 | BS2: ='001 B-'!B10 | BT2: ='001 B-'!B10 | BU2: ='001 B-'!B10 | BV2: ='001 B-'!B10 | BW2: ='001 B-'!B10 | BX2: ='001 B-'!B10 | BY2: ='001 B-'!B10 | BZ2: ='001 B-'!B10 | CA2: ='001 B-'!B10 | CB2: ='001 B-'!B10 | CC2: ='001 B-'!B10 | CD2: ='001 B-'!B10 | CE2: ='001 B-'!B10 | CF2: ='001 B-'!B10 | CG2: ='001 B-'!B10 | CH2: ='001 B-'!B10 | CI2: ='001 B-'!B10 | CJ2: ='001 B-'!B10 | CK2: ='001 B-'!B10 | CL2: ='001 B-'!B10 | CM2: ='001 B-'!B10 | CN2: ='001 B-'!B10 | CO2: ='001 B-'!B10 | CP2: ='001 B-'!B10 | CQ2: ='001 B-'!B10 | CR2: ='001 B-'!B10 | CS2: ='001 B-'!B10 | CT2: ='001 B-'!B10 | CU2: ='001 B-'!B10 | CV2: ='001 B-'!B10 | CW2: ='001 B-'!B10 | CX2: ='001 B-'!B10 | CY2: ='001 B-'!B10 | CZ2: ='001 B-'!B10 | DA2: ='001 B-'!B10 | DB2: ='001 B-'!B10 | DC2: ='001 B-'!B10 | DD2: ='001 B-'!B10 | DE2: ='001 B-'!B10 | DF2: ='001 B-'!B10 | DG2: ='001 B-'!B10 | DH2: ='001 B-'!B10 | DI2: ='001 B-'!B10 | DJ2: ='001 B-'!B10 | DK2: ='001 B-'!B10
A3: * | B3: português europeu | C3: Portuguese | D3: ='001 B-'!C10 -> 2 | E3: ='002 B-'!C10 -> 2 | F3: ='003 T-'!C10 -> 5 | G3: ='003 T-'!C10 -> 5 | H3: ='003 T-'!C10 -> 5 | I3: ='004 T-'!C10 -> 5 | J3: ='004 T-'!C10 -> 5 | K3: ='005 D-'!C10 -> 6 | L3: ='005 D-'!C10 -> 6 | M3: ='005 D-'!C10 -> 6 | N3: ='006 D-'!C10 -> 6 | O3: ='006 D-'!C10 -> 6 | P3: ='007 C-'!C10 -> 120 | Q3: ='007 C-'!C10 -> 120 | R3: ='008 C-'!C10 -> 19 | S3: ='009 C-'!C10 -> 19 | T3: ='009 C-'!C10 -> 19 | U3: ='001 B-'!C10 | V3: ='001 B-'!C10 | W3: ='001 B-'!C10 | X3: ='001 B-'!C10 | Y3: ='001 B-'!C10 | Z3: ='001 B-'!C10 | AA3: ='001 B-'!C10 | AB3: ='001 B-'!C10 | AC3: ='001 B-'!C10 | AD3: ='001 B-'!C10 | AE3: ='001 B-'!C10 | AF3: ='001 B-'!C10 | AG3: ='001 B-'!C10 | AH3: ='001 B-'!C10 | AI3: ='001 B-'!C10 | AJ3: ='001 B-'!C10 | AK3: ='001 B-'!C10 | AL3: ='001 B-'!C10 | AM3: ='001 B-'!C10 | AN3: ='001 B-'!C10 | AO3: ='001 B-'!C10 | AP3: ='001 B-'!C10 | AQ3: ='001 B-'!C10 | AR3: ='001 B-'!C10 | AS3: ='001 B-'!C10 | AT3: ='001 B-'!C10 | AU3: ='001 B-'!C10 | AV3: ='001 B-'!C10 | AW3: ='001 B-'!C10 | AX3: ='001 B-'!C10 | AY3: ='001 B-'!C10 | AZ3: ='001 B-'!C10 | BA3: ='001 B-'!C10 | BB3: ='001 B-'!C10 | BC3: ='001 B-'!C10 | BD3: ='001 B-'!C10 | BE3: ='001 B-'!C10 | BF3: ='001 B-'!C10 | BG3: ='001 B-'!C10 | BH3: ='001 B-'!C10 | BI3: ='001 B-'!C10 | BJ3: ='001 B-'!C10 | BK3: ='001 B-'!C10 | BL3: ='001 B-'!C10 | BM3: ='001 B-'!C10 | BN3: ='001 B-'!C10 | BO3: ='001 B-'!C10 | BP3: ='001 B-'!C10 | BQ3: ='001 B-'!C10 | BR3: ='001 B-'!C10 | BS3: ='001 B-'!C10 | BT3: ='001 B-'!C10 | BU3: ='001 B-'!C10 | BV3: ='001 B-'!C10 | BW3: ='001 B-'!C10 | BX3: ='001 B-'!C10 | BY3: ='001 B-'!C10 | BZ3: ='001 B-'!C10 | CA3: ='001 B-'!C10 | CB3: ='001 B-'!C10 | CC3: ='001 B-'!C10 | CD3: ='001 B-'!C10 | CE3: ='001 B-'!C10 | CF3: ='001 B-'!C10 | CG3: ='001 B-'!C10 | CH3: ='001 B-'!C10 | CI3: ='001 B-'!C10 | CJ3: ='001 B-'!C10 | CK3: ='001 B-'!C10 | CL3: ='001 B-'!C10 | CM3: ='001 B-'!C10 | CN3: ='001 B-'!C10 | CO3: ='001 B-'!C10 | CP3: ='001 B-'!C10 | CQ3: ='001 B-'!C10 | CR3: ='001 B-'!C10 | CS3: ='001 B-'!C10 | CT3: ='001 B-'!C10 | CU3: ='001 B-'!C10 | CV3: ='001 B-'!C10 | CW3: ='001 B-'!C10 | CX3: ='001 B-'!C10 | CY3: ='001 B-'!C10 | CZ3: ='001 B-'!C10 | DA3: ='001 B-'!C10 | DB3: ='001 B-'!C10 | DC3: ='001 B-'!C10 | DD3: ='001 B-'!C10 | DE3: ='001 B-'!C10 | DF3: ='001 B-'!C10 | DG3: ='001 B-'!C10 | DH3: ='001 B-'!C10 | DI3: ='001 B-'!C10 | DJ3: ='001 B-'!C10 | DK3: ='001 B-'!C10
B4: português brasileiro | C4: Brazilian Portuguese | D4: ='001 B-'!D10 -> 2 | E4: ='002 B-'!D10 -> 2 | F4: ='003 T-'!D10 -> 5 | G4: ='003 T-'!D10 -> 5 | H4: ='003 T-'!AM10 -> 34 | I4: ='004 T-'!D10 -> 5 | J4: ='004 T-'!D10 -> 5 | K4: ='005 D-'!D10 -> 6 | L4: ='005 D-'!D10 -> 6 | M4: ='005 D-'!AM10 -> 35 | N4: ='006 D-'!D10 -> 6 | O4: ='006 D-'!D10 -> 6 | P4: ='007 C-'!D10 -> 50 | Q4: ='007 C-'!D10 -> 50 | R4: ='008 C-'!D10 -> 19 | S4: ='009 C-'!D10 -> 19 | T4: ='009 C-'!D10 -> 19 | U4: ='001 B-'!D10 | V4: ='001 B-'!D10 | W4: ='001 B-'!D10 | X4: ='001 B-'!D10 | Y4: ='001 B-'!D10 | Z4: ='001 B-'!D10 | AA4: ='001 B-'!D10 | AB4: ='001 B-'!D10 | AC4: ='001 B-'!D10 | AD4: ='001 B-'!D10 | AE4: ='001 B-'!D10 | AF4: ='001 B-'!D10 | AG4: ='001 B-'!D10 | AH4: ='001 B-'!D10 | AI4: ='001 B-'!D10 | AJ4: ='001 B-'!D10 | AK4: ='001 B-'!D10 | AL4: ='001 B-'!D10 | AM4: ='001 B-'!D10 | AN4: ='001 B-'!D10 | AO4: ='001 B-'!D10 | AP4: ='001 B-'!D10 | AQ4: ='001 B-'!D10 | AR4: ='001 B-'!D10 | AS4: ='001 B-'!D10 | AT4: ='001 B-'!D10 | AU4: ='001 B-'!D10 | AV4: ='001 B-'!D10 | AW4: ='001 B-'!D10 | AX4: ='001 B-'!D10 | AY4: ='001 B-'!D10 | AZ4: ='001 B-'!D10 | BA4: ='001 B-'!D10 | BB4: ='001 B-'!D10 | BC4: ='001 B-'!D10 | BD4: ='001 B-'!D10 | BE4: ='001 B-'!D10 | BF4: ='001 B-'!D10 | BG4: ='001 B-'!D10 | BH4: ='001 B-'!D10 | BI4: ='001 B-'!D10 | BJ4: ='001 B-'!D10 | BK4: ='001 B-'!D10 | BL4: ='001 B-'!D10 | BM4: ='001 B-'!D10 | BN4: ='001 B-'!D10 | BO4: ='001 B-'!D10 | BP4: ='001 B-'!D10 | BQ4: ='001 B-'!D10 | BR4: ='001 B-'!D10 | BS4: ='001 B-'!D10 | BT4: ='001 B-'!D10 | BU4: ='001 B-'!D10 | BV4: ='001 B-'!D10 | BW4: ='001 B-'!D10 | BX4: ='001 B-'!D10 | BY4: ='001 B-'!D10 | BZ4: ='001 B-'!D10 | CA4: ='001 B-'!D10 | CB4: ='001 B-'!D10 | CC4: ='001 B-'!D10 | CD4: ='001 B-'!D10 | CE4: ='001 B-'!D10 | CF4: ='001 B-'!D10 | CG4: ='001 B-'!D10 | CH4: ='001 B-'!D10 | CI4: ='001 B-'!D10 | CJ4: ='001 B-'!D10 | CK4: ='001 B-'!D10 | CL4: ='001 B-'!D10 | CM4: ='001 B-'!D10 | CN4: ='001 B-'!D10 | CO4: ='001 B-'!D10 | CP4: ='001 B-'!D10 | CQ4: ='001 B-'!D10 | CR4: ='001 B-'!D10 | CS4: ='001 B-'!D10 | CT4: ='001 B-'!D10 | CU4: ='001 B-'!D10 | CV4: ='001 B-'!D10 | CW4: ='001 B-'!D10 | CX4: ='001 B-'!D10 | CY4: ='001 B-'!D10 | CZ4: ='001 B-'!D10 | DA4: ='001 B-'!D10 | DB4: ='001 B-'!D10 | DC4: ='001 B-'!D10 | DD4: ='001 B-'!D10 | DE4: ='001 B-'!D10 | DF4: ='001 B-'!D10 | DG4: ='001 B-'!D10 | DH4: ='001 B-'!D10 | DI4: ='001 B-'!D10 | DJ4: ='001 B-'!D10 | DK4: ='001 B-'!D10
A5: * | B5: galego | C5: Galician | D5: ='001 B-'!E10 -> 2 | E5: ='002 B-'!E10 -> 2 | F5: ='003 T-'!E10 -> 5 | G5: ='003 T-'!E10 -> 5 | H5: ='003 T-'!E10 -> 5 | I5: ='004 T-'!E10 -> 5 | J5: ='004 T-'!E10 -> 5 | K5: ='005 D-'!E10 -> 6 | L5: ='005 D-'!E10 -> 6 | M5: ='005 D-'!E10 -> 6 | N5: ='006 D-'!E10 -> 6 | O5: ='006 D-'!E10 -> 6 | P5: ='007 C-'!E10 -> 102 | Q5: ='007 C-'!E10 -> 102 | R5: ='008 C-'!E10 -> 19 | S5: ='009 C-'!E10 -> 19 | T5: ='009 C-'!E10 -> 19 | U5: ='001 B-'!E10 | V5: ='001 B-'!E10 | W5: ='001 B-'!E10 | X5: ='001 B-'!E10 | Y5: ='001 B-'!E10 | Z5: ='001 B-'!E10 | AA5: ='001 B-'!E10 | AB5: ='001 B-'!E10 | AC5: ='001 B-'!E10 | AD5: ='001 B-'!E10 | AE5: ='001 B-'!E10 | AF5: ='001 B-'!E10 | AG5: ='001 B-'!E10 | AH5: ='001 B-'!E10 | AI5: ='001 B-'!E10 | AJ5: ='001 B-'!E10 | AK5: ='001 B-'!E10 | AL5: ='001 B-'!E10 | AM5: ='001 B-'!E10 | AN5: ='001 B-'!E10 | AO5: ='001 B-'!E10 | AP5: ='001 B-'!E10 | AQ5: ='001 B-'!E10 | AR5: ='001 B-'!E10 | AS5: ='001 B-'!E10 | AT5: ='001 B-'!E10 | AU5: ='001 B-'!E10 | AV5: ='001 B-'!E10 | AW5: ='001 B-'!E10 | AX5: ='001 B-'!E10 | AY5: ='001 B-'!E10 | AZ5: ='001 B-'!E10 | BA5: ='001 B-'!E10 | BB5: ='001 B-'!E10 | BC5: ='001 B-'!E10 | BD5: ='001 B-'!E10 | BE5: ='001 B-'!E10 | BF5: ='001 B-'!E10 | BG5: ='001 B-'!E10 | BH5: ='001 B-'!E10 | BI5: ='001 B-'!E10 | BJ5: ='001 B-'!E10 | BK5: ='001 B-'!E10 | BL5: ='001 B-'!E10 | BM5: ='001 B-'!E10 | BN5: ='001 B-'!E10 | BO5: ='001 B-'!E10 | BP5: ='001 B-'!E10 | BQ5: ='001 B-'!E10 | BR5: ='001 B-'!E10 | BS5: ='001 B-'!E10 | BT5: ='001 B-'!E10 | BU5: ='001 B-'!E10 | BV5: ='001 B-'!E10 | BW5: ='001 B-'!E10 | BX5: ='001 B-'!E10 | BY5: ='001 B-'!E10 | BZ5: ='001 B-'!E10 | CA5: ='001 B-'!E10 | CB5: ='001 B-'!E10 | CC5: ='001 B-'!E10 | CD5: ='001 B-'!E10 | CE5: ='001 B-'!E10 | CF5: ='001 B-'!E10 | CG5: ='001 B-'!E10 | CH5: ='001 B-'!E10 | CI5: ='001 B-'!E10 | CJ5: ='001 B-'!E10 | CK5: ='001 B-'!E10 | CL5: ='001 B-'!E10 | CM5: ='001 B-'!E10 | CN5: ='001 B-'!E10 | CO5: ='001 B-'!E10 | CP5: ='001 B-'!E10 | CQ5: ='001 B-'!E10 | CR5: ='001 B-'!E10 | CS5: ='001 B-'!E10 | CT5: ='001 B-'!E10 | CU5: ='001 B-'!E10 | CV5: ='001 B-'!E10 | CW5: ='001 B-'!E10 | CX5: ='001 B-'!E10 | CY5: ='001 B-'!E10 | CZ5: ='001 B-'!E10 | DA5: ='001 B-'!E10 | DB5: ='001 B-'!E10 | DC5: ='001 B-'!E10 | DD5: ='001 B-'!E10 | DE5: ='001 B-'!E10 | DF5: ='001 B-'!E10 | DG5: ='001 B-'!E10 | DH5: ='001 B-'!E10 | DI5: ='001 B-'!E10 | DJ5: ='001 B-'!E10 | DK5: ='001 B-'!E10
B6: asturlleonés | C6: Astur-Leonese | D6: ='001 B-'!F10 -> 2 | E6: ='002 B-'!F10 -> 2 | F6: ='003 T-'!F10 -> 5 | G6: ='003 T-'!F10 -> 5 | H6: ='003 T-'!F10 -> 5 | I6: ='004 T-'!F10 -> 5 | J6: ='004 T-'!F10 -> 5 | K6: ='005 D-'!F10 -> 6 | L6: ='005 D-'!F10 -> 6 | M6: ='005 D-'!F10 -> 6 | N6: ='006 D-'!F10 -> 6 | O6: ='006 D-'!F10 -> 6 | P6: ='007 C-'!F10 -> 44 | Q6: ='007 C-'!F10 -> 44 | R6: ='008 C-'!F10 -> 19 | S6: ='009 C-'!F10 -> 19 | T6: ='009 C-'!F10 -> 19 | U6: ='001 B-'!F10 | V6: ='001 B-'!F10 | W6: ='001 B-'!F10 | X6: ='001 B-'!F10 | Y6: ='001 B-'!F10 | Z6: ='001 B-'!F10 | AA6: ='001 B-'!F10 | AB6: ='001 B-'!F10 | AC6: ='001 B-'!F10 | AD6: ='001 B-'!F10 | AE6: ='001 B-'!F10 | AF6: ='001 B-'!F10 | AG6: ='001 B-'!F10 | AH6: ='001 B-'!F10 | AI6: ='001 B-'!F10 | AJ6: ='001 B-'!F10 | AK6: ='001 B-'!F10 | AL6: ='001 B-'!F10 | AM6: ='001 B-'!F10 | AN6: ='001 B-'!F10 | AO6: ='001 B-'!F10 | AP6: ='001 B-'!F10 | AQ6: ='001 B-'!F10 | AR6: ='001 B-'!F10 | AS6: ='001 B-'!F10 | AT6: ='001 B-'!F10 | AU6: ='001 B-'!F10 | AV6: ='001 B-'!F10 | AW6: ='001 B-'!F10 | AX6: ='001 B-'!F10 | AY6: ='001 B-'!F10 | AZ6: ='001 B-'!F10 | BA6: ='001 B-'!F10 | BB6: ='001 B-'!F10 | BC6: ='001 B-'!F10 | BD6: ='001 B-'!F10 | BE6: ='001 B-'!F10 | BF6: ='001 B-'!F10 | BG6: ='001 B-'!F10 | BH6: ='001 B-'!F10 | BI6: ='001 B-'!F10 | BJ6: ='001 B-'!F10 | BK6: ='001 B-'!F10 | BL6: ='001 B-'!F10 | BM6: ='001 B-'!F10 | BN6: ='001 B-'!F10 | BO6: ='001 B-'!F10 | BP6: ='001 B-'!F10 | BQ6: ='001 B-'!F10 | BR6: ='001 B-'!F10 | BS6: ='001 B-'!F10 | BT6: ='001 B-'!F10 | BU6: ='001 B-'!F10 | BV6: ='001 B-'!F10 | BW6: ='001 B-'!F10 | BX6: ='001 B-'!F10 | BY6: ='001 B-'!F10 | BZ6: ='001 B-'!F10 | CA6: ='001 B-'!F10 | CB6: ='001 B-'!F10 | CC6: ='001 B-'!F10 | CD6: ='001 B-'!F10 | CE6: ='001 B-'!F10 | CF6: ='001 B-'!F10 | CG6: ='001 B-'!F10 | CH6: ='001 B-'!F10 | CI6: ='001 B-'!F10 | CJ6: ='001 B-'!F10 | CK6: ='001 B-'!F10 | CL6: ='001 B-'!F10 | CM6: ='001 B-'!F10 | CN6: ='001 B-'!F10 | CO6: ='001 B-'!F10 | CP6: ='001 B-'!F10 | CQ6: ='001 B-'!F10 | CR6: ='001 B-'!F10 | CS6: ='001 B-'!F10 | CT6: ='001 B-'!F10 | CU6: ='001 B-'!F10 | CV6: ='001 B-'!F10 | CW6: ='001 B-'!F10 | CX6: ='001 B-'!F10 | CY6: ='001 B-'!F10 | CZ6: ='001 B-'!F10 | DA6: ='001 B-'!F10 | DB6: ='001 B-'!F10 | DC6: ='001 B-'!F10 | DD6: ='001 B-'!F10 | DE6: ='001 B-'!F10 | DF6: ='001 B-'!F10 | DG6: ='001 B-'!F10 | DH6: ='001 B-'!F10 | DI6: ='001 B-'!F10 | DJ6: ='001 B-'!F10 | DK6: ='001 B-'!F10
A7: * | B7: castellano | C7: Castilian Spanish | D7: ='001 B-'!G10 -> 2 | E7: ='002 B-'!G10 -> 2 | F7: ='003 T-'!G10 -> 5 | G7: ='003 T-'!G10 -> 5 | H7: ='003 T-'!G10 -> 5 | I7: ='004 T-'!G10 -> 5 | J7: ='004 T-'!G10 -> 5 | K7: ='005 D-'!G10 -> 6 | L7: ='005 D-'!G10 -> 6 | M7: ='005 D-'!G10 -> 6 | N7: ='006 D-'!G10 -> 6 | O7: ='006 D-'!G10 -> 6 | P7: ='007 C-'!G10 -> 44 | Q7: ='007 C-'!G10 -> 44 | R7: ='008 C-'!G10 -> 19 | S7: ='009 C-'!G10 -> 19 | T7: ='009 C-'!G10 -> 19 | U7: ='001 B-'!G10 | V7: ='001 B-'!G10 | W7: ='001 B-'!G10 | X7: ='001 B-'!G10 | Y7: ='001 B-'!G10 | Z7: ='001 B-'!G10 | AA7: ='001 B-'!G10 | AB7: ='001 B-'!G10 | AC7: ='001 B-'!G10 | AD7: ='001 B-'!G10 | AE7: ='001 B-'!G10 | AF7: ='001 B-'!G10 | AG7: ='001 B-'!G10 | AH7: ='001 B-'!G10 | AI7: ='001 B-'!G10 | AJ7: ='001 B-'!G10 | AK7: ='001 B-'!G10 | AL7: ='001 B-'!G10 | AM7: ='001 B-'!G10 | AN7: ='001 B-'!G10 | AO7: ='001 B-'!G10 | AP7: ='001 B-'!G10 | AQ7: ='001 B-'!G10 | AR7: ='001 B-'!G10 | AS7: ='001 B-'!G10 | AT7: ='001 B-'!G10 | AU7: ='001 B-'!G10 | AV7: ='001 B-'!G10 | AW7: ='001 B-'!G10 | AX7: ='001 B-'!G10 | AY7: ='001 B-'!G10 | AZ7: ='001 B-'!G10 | BA7: ='001 B-'!G10 | BB7: ='001 B-'!G10 | BC7: ='001 B-'!G10 | BD7: ='001 B-'!G10 | BE7: ='001 B-'!G10 | BF7: ='001 B-'!G10 | BG7: ='001 B-'!G10 | BH7: ='001 B-'!G10 | BI7: ='001 B-'!G10 | BJ7: ='001 B-'!G10 | BK7: ='001 B-'!G10 | BL7: ='001 B-'!G10 | BM7: ='001 B-'!G10 | BN7: ='001 B-'!G10 | BO7: ='001 B-'!G10 | BP7: ='001 B-'!G10 | BQ7: ='001 B-'!G10 | BR7: ='001 B-'!G10 | BS7: ='001 B-'!G10 | BT7: ='001 B-'!G10 | BU7: ='001 B-'!G10 | BV7: ='001 B-'!G10 | BW7: ='001 B-'!G10 | BX7: ='001 B-'!G10 | BY7: ='001 B-'!G10 | BZ7: ='001 B-'!G10 | CA7: ='001 B-'!G10 | CB7: ='001 B-'!G10 | CC7: ='001 B-'!G10 | CD7: ='001 B-'!G10 | CE7: ='001 B-'!G10 | CF7: ='001 B-'!G10 | CG7: ='001 B-'!G10 | CH7: ='001 B-'!G10 | CI7: ='001 B-'!G10 | CJ7: ='001 B-'!G10 | CK7: ='001 B-'!G10 | CL7: ='001 B-'!G10 | CM7: ='001 B-'!G10 | CN7: ='001 B-'!G10 | CO7: ='001 B-'!G10 | CP7: ='001 B-'!G10 | CQ7: ='001 B-'!G10 | CR7: ='001 B-'!G10 | CS7: ='001 B-'!G10 | CT7: ='001 B-'!G10 | CU7: ='001 B-'!G10 | CV7: ='001 B-'!G10 | CW7: ='001 B-'!G10 | CX7: ='001 B-'!G10 | CY7: ='001 B-'!G10 | CZ7: ='001 B-'!G10 | DA7: ='001 B-'!G10 | DB7: ='001 B-'!G10 | DC7: ='001 B-'!G10 | DD7: ='001 B-'!G10 | DE7: ='001 B-'!G10 | DF7: ='001 B-'!G10 | DG7: ='001 B-'!G10 | DH7: ='001 B-'!G10 | DI7: ='001 B-'!G10 | DJ7: ='001 B-'!G10 | DK7: ='001 B-'!G10
B8: andaluz | C8: Andalusian Spanish | D8: ='001 B-'!H10 -> 2 | E8: ='002 B-'!H10 -> 2 | F8: ='003 T-'!H10 -> 5 | G8: ='003 T-'!H10 -> 5 | H8: ='003 T-'!H10 -> 5 | I8: ='004 T-'!H10 -> 5 | J8: ='004 T-'!H10 -> 5 | K8: ='005 D-'!H10 -> 6 | L8: ='005 D-'!H10 -> 6 | M8: ='005 D-'!H10 -> 6 | N8: ='006 D-'!H10 -> 6 | O8: ='006 D-'!H10 -> 6 | P8: ='007 C-'!H10 -> 46 | Q8: ='007 C-'!H10 -> 46 | R8: ='008 C-'!H10 -> 19 | S8: ='009 C-'!H10 -> 19 | T8: ='009 C-'!H10 -> 19 | U8: ='001 B-'!H10 | V8: ='001 B-'!H10 | W8: ='001 B-'!H10 | X8: ='001 B-'!H10 | Y8: ='001 B-'!H10 | Z8: ='001 B-'!H10 | AA8: ='001 B-'!H10 | AB8: ='001 B-'!H10 | AC8: ='001 B-'!H10 | AD8: ='001 B-'!H10 | AE8: ='001 B-'!H10 | AF8: ='001 B-'!H10 | AG8: ='001 B-'!H10 | AH8: ='001 B-'!H10 | AI8: ='001 B-'!H10 | AJ8: ='001 B-'!H10 | AK8: ='001 B-'!H10 | AL8: ='001 B-'!H10 | AM8: ='001 B-'!H10 | AN8: ='001 B-'!H10 | AO8: ='001 B-'!H10 | AP8: ='001 B-'!H10 | AQ8: ='001 B-'!H10 | AR8: ='001 B-'!H10 | AS8: ='001 B-'!H10 | AT8: ='001 B-'!H10 | AU8: ='001 B-'!H10 | AV8: ='001 B-'!H10 | AW8: ='001 B-'!H10 | AX8: ='001 B-'!H10 | AY8: ='001 B-'!H10 | AZ8: ='001 B-'!H10 | BA8: ='001 B-'!H10 | BB8: ='001 B-'!H10 | BC8: ='001 B-'!H10 | BD8: ='001 B-'!H10 | BE8: ='001 B-'!H10 | BF8: ='001 B-'!H10 | BG8: ='001 B-'!H10 | BH8: ='001 B-'!H10 | BI8: ='001 B-'!H10 | BJ8: ='001 B-'!H10 | BK8: ='001 B-'!H10 | BL8: ='001 B-'!H10 | BM8: ='001 B-'!H10 | BN8: ='001 B-'!H10 | BO8: ='001 B-'!H10 | BP8: ='001 B-'!H10 | BQ8: ='001 B-'!H10 | BR8: ='001 B-'!H10 | BS8: ='001 B-'!H10 | BT8: ='001 B-'!H10 | BU8: ='001 B-'!H10 | BV8: ='001 B-'!H10 | BW8: ='001 B-'!H10 | BX8: ='001 B-'!H10 | BY8: ='001 B-'!H10 | BZ8: ='001 B-'!H10 | CA8: ='001 B-'!H10 | CB8: ='001 B-'!H10 | CC8: ='001 B-'!H10 | CD8: ='001 B-'!H10 | CE8: ='001 B-'!H10 | CF8: ='001 B-'!H10 | CG8: ='001 B-'!H10 | CH8: ='001 B-'!H10 | CI8: ='001 B-'!H10 | CJ8: ='001 B-'!H10 | CK8: ='001 B-'!H10 | CL8: ='001 B-'!H10 | CM8: ='001 B-'!H10 | CN8: ='001 B-'!H10 | CO8: ='001 B-'!H10 | CP8: ='001 B-'!H10 | CQ8: ='001 B-'!H10 | CR8: ='001 B-'!H10 | CS8: ='001 B-'!H10 | CT8: ='001 B-'!H10 | CU8: ='001 B-'!H10 | CV8: ='001 B-'!H10 | CW8: ='001 B-'!H10 | CX8: ='001 B-'!H10 | CY8: ='001 B-'!H10 | CZ8: ='001 B-'!H10 | DA8: ='001 B-'!H10 | DB8: ='001 B-'!H10 | DC8: ='001 B-'!H10 | DD8: ='001 B-'!H10 | DE8: ='001 B-'!H10 | DF8: ='001 B-'!H10 | DG8: ='001 B-'!H10 | DH8: ='001 B-'!H10 | DI8: ='001 B-'!H10 | DJ8: ='001 B-'!H10 | DK8: ='001 B-'!H10
B9: español de América | C9: American Spanish | D9: ='001 B-'!I10 -> 2 | E9: ='002 B-'!I10 -> 2 | F9: ='003 T-'!I10 -> 5 | G9: ='003 T-'!I10 -> 5 | H9: ='003 T-'!I10 -> 5 | I9: ='004 T-'!I10 -> 5 | J9: ='004 T-'!I10 -> 5 | K9: ='005 D-'!I10 -> 6 | L9: ='005 D-'!I10 -> 6 | M9: ='005 D-'!I10 -> 6 | N9: ='006 D-'!I10 -> 6 | O9: ='006 D-'!I10 -> 6 | P9: ='007 C-'!I10 -> 50 | Q9: ='007 C-'!I10 -> 50 | R9: ='008 C-'!I10 -> 19 | S9: ='009 C-'!I10 -> 19 | T9: ='009 C-'!I10 -> 19 | U9: ='001 B-'!I10 | V9: ='001 B-'!I10 | W9: ='001 B-'!I10 | X9: ='001 B-'!I10 | Y9: ='001 B-'!I10 | Z9: ='001 B-'!I10 | AA9: ='001 B-'!I10 | AB9: ='001 B-'!I10 | AC9: ='001 B-'!I10 | AD9: ='001 B-'!I10 | AE9: ='001 B-'!I10 | AF9: ='001 B-'!I10 | AG9: ='001 B-'!I10 | AH9: ='001 B-'!I10 | AI9: ='001 B-'!I10 | AJ9: ='001 B-'!I10 | AK9: ='001 B-'!I10 | AL9: ='001 B-'!I10 | AM9: ='001 B-'!I10 | AN9: ='001 B-'!I10 | AO9: ='001 B-'!I10 | AP9: ='001 B-'!I10 | AQ9: ='001 B-'!I10 | AR9: ='001 B-'!I10 | AS9: ='001 B-'!I10 | AT9: ='001 B-'!I10 | AU9: ='001 B-'!I10 | AV9: ='001 B-'!I10 | AW9: ='001 B-'!I10 | AX9: ='001 B-'!I10 | AY9: ='001 B-'!I10 | AZ9: ='001 B-'!I10 | BA9: ='001 B-'!I10 | BB9: ='001 B-'!I10 | BC9: ='001 B-'!I10 | BD9: ='001 B-'!I10 | BE9: ='001 B-'!I10 | BF9: ='001 B-'!I10 | BG9: ='001 B-'!I10 | BH9: ='001 B-'!I10 | BI9: ='001 B-'!I10 | BJ9: ='001 B-'!I10 | BK9: ='001 B-'!I10 | BL9: ='001 B-'!I10 | BM9: ='001 B-'!I10 | BN9: ='001 B-'!I10 | BO9: ='001 B-'!I10 | BP9: ='001 B-'!I10 | BQ9: ='001 B-'!I10 | BR9: ='001 B-'!I10 | BS9: ='001 B-'!I10 | BT9: ='001 B-'!I10 | BU9: ='001 B-'!I10 | BV9: ='001 B-'!I10 | BW9: ='001 B-'!I10 | BX9: ='001 B-'!I10 | BY9: ='001 B-'!I10 | BZ9: ='001 B-'!I10 | CA9: ='001 B-'!I10 | CB9: ='001 B-'!I10 | CC9: ='001 B-'!I10 | CD9: ='001 B-'!I10 | CE9: ='001 B-'!I10 | CF9: ='001 B-'!I10 | CG9: ='001 B-'!I10 | CH9: ='001 B-'!I10 | CI9: ='001 B-'!I10 | CJ9: ='001 B-'!I10 | CK9: ='001 B-'!I10 | CL9: ='001 B-'!I10 | CM9: ='001 B-'!I10 | CN9: ='001 B-'!I10 | CO9: ='001 B-'!I10 | CP9: ='001 B-'!I10 | CQ9: ='001 B-'!I10 | CR9: ='001 B-'!I10 | CS9: ='001 B-'!I10 | CT9: ='001 B-'!I10 | CU9: ='001 B-'!I10 | CV9: ='001 B-'!I10 | CW9: ='001 B-'!I10 | CX9: ='001 B-'!I10 | CY9: ='001 B-'!I10 | CZ9: ='001 B-'!I10 | DA9: ='001 B-'!I10 | DB9: ='001 B-'!I10 | DC9: ='001 B-'!I10 | DD9: ='001 B-'!I10 | DE9: ='001 B-'!I10 | DF9: ='001 B-'!I10 | DG9: ='001 B-'!I10 | DH9: ='001 B-'!I10 | DI9: ='001 B-'!I10 | DJ9: ='001 B-'!I10 | DK9: ='001 B-'!I10
B10: aragonés | C10: Aragonese | D10: ='001 B-'!J10 -> 2 | E10: ='002 B-'!J10 -> 2 | F10: ='003 T-'!J10 -> 5 | G10: ='003 T-'!J10 -> 5 | H10: ='003 T-'!J10 -> 5 | I10: ='004 T-'!J10 -> 5 | J10: ='004 T-'!J10 -> 5 | K10: ='005 D-'!J10 -> 6 | L10: ='005 D-'!J10 -> 6 | M10: ='005 D-'!J10 -> 6 | N10: ='006 D-'!J10 -> 6 | O10: ='006 D-'!J10 -> 6 | P10: ='007 C-'!J10 -> 44 | Q10: ='007 C-'!J10 -> 44 | R10: ='008 C-'!J10 -> 19 | S10: ='009 C-'!J10 -> 19 | T10: ='009 C-'!J10 -> 19 | U10: ='001 B-'!J10 | V10: ='001 B-'!J10 | W10: ='001 B-'!J10 | X10: ='001 B-'!J10 | Y10: ='001 B-'!J10 | Z10: ='001 B-'!J10 | AA10: ='001 B-'!J10 | AB10: ='001 B-'!J10 | AC10: ='001 B-'!J10 | AD10: ='001 B-'!J10 | AE10: ='001 B-'!J10 | AF10: ='001 B-'!J10 | AG10: ='001 B-'!J10 | AH10: ='001 B-'!J10 | AI10: ='001 B-'!J10 | AJ10: ='001 B-'!J10 | AK10: ='001 B-'!J10 | AL10: ='001 B-'!J10 | AM10: ='001 B-'!J10 | AN10: ='001 B-'!J10 | AO10: ='001 B-'!J10 | AP10: ='001 B-'!J10 | AQ10: ='001 B-'!J10 | AR10: ='001 B-'!J10 | AS10: ='001 B-'!J10 | AT10: ='001 B-'!J10 | AU10: ='001 B-'!J10 | AV10: ='001 B-'!J10 | AW10: ='001 B-'!J10 | AX10: ='001 B-'!J10 | AY10: ='001 B-'!J10 | AZ10: ='001 B-'!J10 | BA10: ='001 B-'!J10 | BB10: ='001 B-'!J10 | BC10: ='001 B-'!J10 | BD10: ='001 B-'!J10 | BE10: ='001 B-'!J10 | BF10: ='001 B-'!J10 | BG10: ='001 B-'!J10 | BH10: ='001 B-'!J10 | BI10: ='001 B-'!J10 | BJ10: ='001 B-'!J10 | BK10: ='001 B-'!J10 | BL10: ='001 B-'!J10 | BM10: ='001 B-'!J10 | BN10: ='001 B-'!J10 | BO10: ='001 B-'!J10 | BP10: ='001 B-'!J10 | BQ10: ='001 B-'!J10 | BR10: ='001 B-'!J10 | BS10: ='001 B-'!J10 | BT10: ='001 B-'!J10 | BU10: ='001 B-'!J10 | BV10: ='001 B-'!J10 | BW10: ='001 B-'!J10 | BX10: ='001 B-'!J10 | BY10: ='001 B-'!J10 | BZ10: ='001 B-'!J10 | CA10: ='001 B-'!J10 | CB10: ='001 B-'!J10 | CC10: ='001 B-'!J10 | CD10: ='001 B-'!J10 | CE10: ='001 B-'!J10 | CF10: ='001 B-'!J10 | CG10: ='001 B-'!J10 | CH10: ='001 B-'!J10 | CI10: ='001 B-'!J10 | CJ10: ='001 B-'!J10 | CK10: ='001 B-'!J10 | CL10: ='001 B-'!J10 | CM10: ='001 B-'!J10 | CN10: ='001 B-'!J10 | CO10: ='001 B-'!J10 | CP10: ='001 B-'!J10 | CQ10: ='001 B-'!J10 | CR10: ='001 B-'!J10 | CS10: ='001 B-'!J10 | CT10: ='001 B-'!J10 | CU10: ='001 B-'!J10 | CV10: ='001 B-'!J10 | CW10: ='001 B-'!J10 | CX10: ='001 B-'!J10 | CY10: ='001 B-'!J10 | CZ10: ='001 B-'!J10 | DA10: ='001 B-'!J10 | DB10: ='001 B-'!J10 | DC10: ='001 B-'!J10 | DD10: ='001 B-'!J10 | DE10: ='001 B-'!J10 | DF10: ='001 B-'!J10 | DG10: ='001 B-'!J10 | DH10: ='001 B-'!J10 | DI10: ='001 B-'!J10 | DJ10: ='001 B-'!J10 | DK10: ='001 B-'!J10
A11: * | B11: català | C11: Catalan | D11: ='001 B-'!K10 -> 2 | E11: ='002 B-'!K10 -> 2 | F11: ='003 T-'!K10 -> 5 | G11: ='003 T-'!K10 -> 5 | H11: ='003 T-'!K10 -> 5 | I11: ='004 T-'!K10 -> 5 | J11: ='004 T-'!K10 -> 5 | K11: ='005 D-'!K10 -> 6 | L11: ='005 D-'!K10 -> 6 | M11: ='005 D-'!K10 -> 6 | N11: ='006 D-'!K10 -> 6 | O11: ='006 D-'!K10 -> 6 | P11: ='007 C-'!K10 -> 52 | Q11: ='007 C-'!K10 -> 52 | R11: ='008 C-'!K10 -> 19 | S11: ='009 C-'!K10 -> 19 | T11: ='009 C-'!K10 -> 19 | U11: ='001 B-'!K10 | V11: ='001 B-'!K10 | W11: ='001 B-'!K10 | X11: ='001 B-'!K10 | Y11: ='001 B-'!K10 | Z11: ='001 B-'!K10 | AA11: ='001 B-'!K10 | AB11: ='001 B-'!K10 | AC11: ='001 B-'!K10 | AD11: ='001 B-'!K10 | AE11: ='001 B-'!K10 | AF11: ='001 B-'!K10 | AG11: ='001 B-'!K10 | AH11: ='001 B-'!K10 | AI11: ='001 B-'!K10 | AJ11: ='001 B-'!K10 | AK11: ='001 B-'!K10 | AL11: ='001 B-'!K10 | AM11: ='001 B-'!K10 | AN11: ='001 B-'!K10 | AO11: ='001 B-'!K10 | AP11: ='001 B-'!K10 | AQ11: ='001 B-'!K10 | AR11: ='001 B-'!K10 | AS11: ='001 B-'!K10 | AT11: ='001 B-'!K10 | AU11: ='001 B-'!K10 | AV11: ='001 B-'!K10 | AW11: ='001 B-'!K10 | AX11: ='001 B-'!K10 | AY11: ='001 B-'!K10 | AZ11: ='001 B-'!K10 | BA11: ='001 B-'!K10 | BB11: ='001 B-'!K10 | BC11: ='001 B-'!K10 | BD11: ='001 B-'!K10 | BE11: ='001 B-'!K10 | BF11: ='001 B-'!K10 | BG11: ='001 B-'!K10 | BH11: ='001 B-'!K10 | BI11: ='001 B-'!K10 | BJ11: ='001 B-'!K10 | BK11: ='001 B-'!K10 | BL11: ='001 B-'!K10 | BM11: ='001 B-'!K10 | BN11: ='001 B-'!K10 | BO11: ='001 B-'!K10 | BP11: ='001 B-'!K10 | BQ11: ='001 B-'!K10 | BR11: ='001 B-'!K10 | BS11: ='001 B-'!K10 | BT11: ='001 B-'!K10 | BU11: ='001 B-'!K10 | BV11: ='001 B-'!K10 | BW11: ='001 B-'!K10 | BX11: ='001 B-'!K10 | BY11: ='001 B-'!K10 | BZ11: ='001 B-'!K10 | CA11: ='001 B-'!K10 | CB11: ='001 B-'!K10 | CC11: ='001 B-'!K10 | CD11: ='001 B-'!K10 | CE11: ='001 B-'!K10 | CF11: ='001 B-'!K10 | CG11: ='001 B-'!K10 | CH11: ='001 B-'!K10 | CI11: ='001 B-'!K10 | CJ11: ='001 B-'!K10 | CK11: ='001 B-'!K10 | CL11: ='001 B-'!K10 | CM11: ='001 B-'!K10 | CN11: ='001 B-'!K10 | CO11: ='001 B-'!K10 | CP11: ='001 B-'!K10 | CQ11: ='001 B-'!K10 | CR11: ='001 B-'!K10 | CS11: ='001 B-'!K10 | CT11: ='001 B-'!K10 | CU11: ='001 B-'!K10 | CV11: ='001 B-'!K10 | CW11: ='001 B-'!K10 | CX11: ='001 B-'!K10 | CY11: ='001 B-'!K10 | CZ11: ='001 B-'!K10 | DA11: ='001 B-'!K10 | DB11: ='001 B-'!K10 | DC11: ='001 B-'!K10 | DD11: ='001 B-'!K10 | DE11: ='001 B-'!K10 | DF11: ='001 B-'!K10 | DG11: ='001 B-'!K10 | DH11: ='001 B-'!K10 | DI11: ='001 B-'!K10 | DJ11: ='001 B-'!K10 | DK11: ='001 B-'!K10
B12: valencià | C12: Valencian | D12: ='001 B-'!L10 -> 2 | E12: ='002 B-'!L10 -> 2 | F12: ='003 T-'!L10 -> 5 | G12: ='003 T-'!L10 -> 5 | H12: ='003 T-'!L10 -> 5 | I12: ='004 T-'!L10 -> 5 | J12: ='004 T-'!L10 -> 5 | K12: ='005 D-'!L10 -> 6 | L12: ='005 D-'!L10 -> 6 | M12: ='005 D-'!L10 -> 6 | N12: ='006 D-'!L10 -> 6 | O12: ='006 D-'!L10 -> 6 | P12: ='007 C-'!L10 -> 52 | Q12: ='007 C-'!L10 -> 52 | R12: ='008 C-'!L10 -> 19 | S12: ='009 C-'!L10 -> 19 | T12: ='009 C-'!L10 -> 19 | U12: ='001 B-'!L10 | V12: ='001 B-'!L10 | W12: ='001 B-'!L10 | X12: ='001 B-'!L10 | Y12: ='001 B-'!L10 | Z12: ='001 B-'!L10 | AA12: ='001 B-'!L10 | AB12: ='001 B-'!L10 | AC12: ='001 B-'!L10 | AD12: ='001 B-'!L10 | AE12: ='001 B-'!L10 | AF12: ='001 B-'!L10 | AG12: ='001 B-'!L10 | AH12: ='001 B-'!L10 | AI12: ='001 B-'!L10 | AJ12: ='001 B-'!L10 | AK12: ='001 B-'!L10 | AL12: ='001 B-'!L10 | AM12: ='001 B-'!L10 | AN12: ='001 B-'!L10 | AO12: ='001 B-'!L10 | AP12: ='001 B-'!L10 | AQ12: ='001 B-'!L10 | AR12: ='001 B-'!L10 | AS12: ='001 B-'!L10 | AT12: ='001 B-'!L10 | AU12: ='001 B-'!L10 | AV12: ='001 B-'!L10 | AW12: ='001 B-'!L10 | AX12: ='001 B-'!L10 | AY12: ='001 B-'!L10 | AZ12: ='001 B-'!L10 | BA12: ='001 B-'!L10 | BB12: ='001 B-'!L10 | BC12: ='001 B-'!L10 | BD12: ='001 B-'!L10 | BE12: ='001 B-'!L10 | BF12: ='001 B-'!L10 | BG12: ='001 B-'!L10 | BH12: ='001 B-'!L10 | BI12: ='001 B-'!L10 | BJ12: ='001 B-'!L10 | BK12: ='001 B-'!L10 | BL12: ='001 B-'!L10 | BM12: ='001 B-'!L10 | BN12: ='001 B-'!L10 | BO12: ='001 B-'!L10 | BP12: ='001 B-'!L10 | BQ12: ='001 B-'!L10 | BR12: ='001 B-'!L10 | BS12: ='001 B-'!L10 | BT12: ='001 B-'!L10 | BU12: ='001 B-'!L10 | BV12: ='001 B-'!L10 | BW12: ='001 B-'!L10 | BX12: ='001 B-'!L10 | BY12: ='001 B-'!L10 | BZ12: ='001 B-'!L10 | CA12: ='001 B-'!L10 | CB12: ='001 B-'!L10 | CC12: ='001 B-'!L10 | CD12: ='001 B-'!L10 | CE12: ='001 B-'!L10 | CF12: ='001 B-'!L10 | CG12: ='001 B-'!L10 | CH12: ='001 B-'!L10 | CI12: ='001 B-'!L10 | CJ12: ='001 B-'!L10 | CK12: ='001 B-'!L10 | CL12: ='001 B-'!L10 | CM12: ='001 B-'!L10 | CN12: ='001 B-'!L10 | CO12: ='001 B-'!L10 | CP12: ='001 B-'!L10 | CQ12: ='001 B-'!L10 | CR12: ='001 B-'!L10 | CS12: ='001 B-'!L10 | CT12: ='001 B-'!L10 | CU12: ='001 B-'!L10 | CV12: ='001 B-'!L10 | CW12: ='001 B-'!L10 | CX12: ='001 B-'!L10 | CY12: ='001 B-'!L10 | CZ12: ='001 B-'!L10 | DA12: ='001 B-'!L10 | DB12: ='001 B-'!L10 | DC12: ='001 B-'!L10 | DD12: ='001 B-'!L10 | DE12: ='001 B-'!L10 | DF12: ='001 B-'!L10 | DG12: ='001 B-'!L10 | DH12: ='001 B-'!L10 | DI12: ='001 B-'!L10 | DJ12: ='001 B-'!L10 | DK12: ='001 B-'!L10
B13: balear | C13: Balearic | D13: ='001 B-'!M10 -> 2 | E13: ='002 B-'!M10 -> 2 | F13: ='003 T-'!M10 -> 5 | G13: ='003 T-'!M10 -> 5 | H13: ='003 T-'!M10 -> 5 | I13: ='004 T-'!M10 -> 5 | J13: ='004 T-'!M10 -> 5 | K13: ='005 D-'!M10 -> 6 | L13: ='005 D-'!M10 -> 6 | M13: ='005 D-'!M10 -> 6 | N13: ='006 D-'!M10 -> 6 | O13: ='006 D-'!M10 -> 6 | P13: ='007 C-'!M10 -> 52 | Q13: ='007 C-'!M10 -> 52 | R13: ='008 C-'!M10 -> 19 | S13: ='009 C-'!M10 -> 19 | T13: ='009 C-'!M10 -> 19 | U13: ='001 B-'!M10 | V13: ='001 B-'!M10 | W13: ='001 B-'!M10 | X13: ='001 B-'!M10 | Y13: ='001 B-'!M10 | Z13: ='001 B-'!M10 | AA13: ='001 B-'!M10 | AB13: ='001 B-'!M10 | AC13: ='001 B-'!M10 | AD13: ='001 B-'!M10 | AE13: ='001 B-'!M10 | AF13: ='001 B-'!M10 | AG13: ='001 B-'!M10 | AH13: ='001 B-'!M10 | AI13: ='001 B-'!M10 | AJ13: ='001 B-'!M10 | AK13: ='001 B-'!M10 | AL13: ='001 B-'!M10 | AM13: ='001 B-'!M10 | AN13: ='001 B-'!M10 | AO13: ='001 B-'!M10 | AP13: ='001 B-'!M10 | AQ13: ='001 B-'!M10 | AR13: ='001 B-'!M10 | AS13: ='001 B-'!M10 | AT13: ='001 B-'!M10 | AU13: ='001 B-'!M10 | AV13: ='001 B-'!M10 | AW13: ='001 B-'!M10 | AX13: ='001 B-'!M10 | AY13: ='001 B-'!M10 | AZ13: ='001 B-'!M10 | BA13: ='001 B-'!M10 | BB13: ='001 B-'!M10 | BC13: ='001 B-'!M10 | BD13: ='001 B-'!M10 | BE13: ='001 B-'!M10 | BF13: ='001 B-'!M10 | BG13: ='001 B-'!M10 | BH13: ='001 B-'!M10 | BI13: ='001 B-'!M10 | BJ13: ='001 B-'!M10 | BK13: ='001 B-'!M10 | BL13: ='001 B-'!M10 | BM13: ='001 B-'!M10 | BN13: ='001 B-'!M10 | BO13: ='001 B-'!M10 | BP13: ='001 B-'!M10 | BQ13: ='001 B-'!M10 | BR13: ='001 B-'!M10 | BS13: ='001 B-'!M10 | BT13: ='001 B-'!M10 | BU13: ='001 B-'!M10 | BV13: ='001 B-'!M10 | BW13: ='001 B-'!M10 | BX13: ='001 B-'!M10 | BY13: ='001 B-'!M10 | BZ13: ='001 B-'!M10 | CA13: ='001 B-'!M10 | CB13: ='001 B-'!M10 | CC13: ='001 B-'!M10 | CD13: ='001 B-'!M10 | CE13: ='001 B-'!M10 | CF13: ='001 B-'!M10 | CG13: ='001 B-'!M10 | CH13: ='001 B-'!M10 | CI13: ='001 B-'!M10 | CJ13: ='001 B-'!M10 | CK13: ='001 B-'!M10 | CL13: ='001 B-'!M10 | CM13: ='001 B-'!M10 | CN13: ='001 B-'!M10 | CO13: ='001 B-'!M10 | CP13: ='001 B-'!M10 | CQ13: ='001 B-'!M10 | CR13: ='001 B-'!M10 | CS13: ='001 B-'!M10 | CT13: ='001 B-'!M10 | CU13: ='001 B-'!M10 | CV13: ='001 B-'!M10 | CW13: ='001 B-'!M10 | CX13: ='001 B-'!M10 | CY13: ='001 B-'!M10 | CZ13: ='001 B-'!M10 | DA13: ='001 B-'!M10 | DB13: ='001 B-'!M10 | DC13: ='001 B-'!M10 | DD13: ='001 B-'!M10 | DE13: ='001 B-'!M10 | DF13: ='001 B-'!M10 | DG13: ='001 B-'!M10 | DH13: ='001 B-'!M10 | DI13: ='001 B-'!M10 | DJ13: ='001 B-'!M10 | DK13: ='001 B-'!M10
A14: * | B14: occitan | C14: Occitan | D14: ='001 B-'!N10 -> 2 | E14: ='002 B-'!N10 -> 2 | F14: ='003 T-'!N10 -> 5 | G14: ='003 T-'!N10 -> 5 | H14: ='003 T-'!N10 -> 5 | I14: ='004 T-'!N10 -> 5 | J14: ='004 T-'!N10 -> 5 | K14: ='005 D-'!N10 -> 6 | L14: ='005 D-'!N10 -> 6 | M14: ='005 D-'!N10 -> 6 | N14: ='006 D-'!N10 -> 6 | O14: ='006 D-'!N10 -> 6 | P14: ='007 C-'!N10 -> 52 | Q14: ='007 C-'!N10 -> 52 | R14: ='008 C-'!N10 -> 105 | S14: ='009 C-'!N10 -> 19 | T14: ='009 C-'!N10 -> 19 | U14: ='001 B-'!N10 | V14: ='001 B-'!N10 | W14: ='001 B-'!N10 | X14: ='001 B-'!N10 | Y14: ='001 B-'!N10 | Z14: ='001 B-'!N10 | AA14: ='001 B-'!N10 | AB14: ='001 B-'!N10 | AC14: ='001 B-'!N10 | AD14: ='001 B-'!N10 | AE14: ='001 B-'!N10 | AF14: ='001 B-'!N10 | AG14: ='001 B-'!N10 | AH14: ='001 B-'!N10 | AI14: ='001 B-'!N10 | AJ14: ='001 B-'!N10 | AK14: ='001 B-'!N10 | AL14: ='001 B-'!N10 | AM14: ='001 B-'!N10 | AN14: ='001 B-'!N10 | AO14: ='001 B-'!N10 | AP14: ='001 B-'!N10 | AQ14: ='001 B-'!N10 | AR14: ='001 B-'!N10 | AS14: ='001 B-'!N10 | AT14: ='001 B-'!N10 | AU14: ='001 B-'!N10 | AV14: ='001 B-'!N10 | AW14: ='001 B-'!N10 | AX14: ='001 B-'!N10 | AY14: ='001 B-'!N10 | AZ14: ='001 B-'!N10 | BA14: ='001 B-'!N10 | BB14: ='001 B-'!N10 | BC14: ='001 B-'!N10 | BD14: ='001 B-'!N10 | BE14: ='001 B-'!N10 | BF14: ='001 B-'!N10 | BG14: ='001 B-'!N10 | BH14: ='001 B-'!N10 | BI14: ='001 B-'!N10 | BJ14: ='001 B-'!N10 | BK14: ='001 B-'!N10 | BL14: ='001 B-'!N10 | BM14: ='001 B-'!N10 | BN14: ='001 B-'!N10 | BO14: ='001 B-'!N10 | BP14: ='001 B-'!N10 | BQ14: ='001 B-'!N10 | BR14: ='001 B-'!N10 | BS14: ='001 B-'!N10 | BT14: ='001 B-'!N10 | BU14: ='001 B-'!N10 | BV14: ='001 B-'!N10 | BW14: ='001 B-'!N10 | BX14: ='001 B-'!N10 | BY14: ='001 B-'!N10 | BZ14: ='001 B-'!N10 | CA14: ='001 B-'!N10 | CB14: ='001 B-'!N10 | CC14: ='001 B-'!N10 | CD14: ='001 B-'!N10 | CE14: ='001 B-'!N10 | CF14: ='001 B-'!N10 | CG14: ='001 B-'!N10 | CH14: ='001 B-'!N10 | CI14: ='001 B-'!N10 | CJ14: ='001 B-'!N10 | CK14: ='001 B-'!N10 | CL14: ='001 B-'!N10 | CM14: ='001 B-'!N10 | CN14: ='001 B-'!N10 | CO14: ='001 B-'!N10 | CP14: ='001 B-'!N10 | CQ14: ='001 B-'!N10 | CR14: ='001 B-'!N10 | CS14: ='001 B-'!N10 | CT14: ='001 B-'!N10 | CU14: ='001 B-'!N10 | CV14: ='001 B-'!N10 | CW14: ='001 B-'!N10 | CX14: ='001 B-'!N10 | CY14: ='001 B-'!N10 | CZ14: ='001 B-'!N10 | DA14: ='001 B-'!N10 | DB14: ='001 B-'!N10 | DC14: ='001 B-'!N10 | DD14: ='001 B-'!N10 | DE14: ='001 B-'!N10 | DF14: ='001 B-'!N10 | DG14: ='001 B-'!N10 | DH14: ='001 B-'!N10 | DI14: ='001 B-'!N10 | DJ14: ='001 B-'!N10 | DK14: ='001 B-'!N10
B15: gascon | C15: Gascon | D15: ='001 B-'!O10 -> 2 | E15: ='002 B-'!O10 -> 2 | F15: ='003 T-'!O10 -> 5 | G15: ='003 T-'!O10 -> 5 | H15: ='003 T-'!O10 -> 5 | I15: ='004 T-'!O10 -> 5 | J15: ='004 T-'!O10 -> 5 | K15: ='005 D-'!O10 -> 6 | L15: ='005 D-'!O10 -> 6 | M15: ='005 D-'!O10 -> 6 | N15: ='006 D-'!O10 -> 6 | O15: ='006 D-'!O10 -> 6 | P15: ='007 C-'!O10 -> 52 | Q15: ='007 C-'!O10 -> 52 | R15: ='008 C-'!O10 -> 19 | S15: ='009 C-'!O10 -> 19 | T15: ='009 C-'!O10 -> 19 | U15: ='001 B-'!O10 | V15: ='001 B-'!O10 | W15: ='001 B-'!O10 | X15: ='001 B-'!O10 | Y15: ='001 B-'!O10 | Z15: ='001 B-'!O10 | AA15: ='001 B-'!O10 | AB15: ='001 B-'!O10 | AC15: ='001 B-'!O10 | AD15: ='001 B-'!O10 | AE15: ='001 B-'!O10 | AF15: ='001 B-'!O10 | AG15: ='001 B-'!O10 | AH15: ='001 B-'!O10 | AI15: ='001 B-'!O10 | AJ15: ='001 B-'!O10 | AK15: ='001 B-'!O10 | AL15: ='001 B-'!O10 | AM15: ='001 B-'!O10 | AN15: ='001 B-'!O10 | AO15: ='001 B-'!O10 | AP15: ='001 B-'!O10 | AQ15: ='001 B-'!O10 | AR15: ='001 B-'!O10 | AS15: ='001 B-'!O10 | AT15: ='001 B-'!O10 | AU15: ='001 B-'!O10 | AV15: ='001 B-'!O10 | AW15: ='001 B-'!O10 | AX15: ='001 B-'!O10 | AY15: ='001 B-'!O10 | AZ15: ='001 B-'!O10 | BA15: ='001 B-'!O10 | BB15: ='001 B-'!O10 | BC15: ='001 B-'!O10 | BD15: ='001 B-'!O10 | BE15: ='001 B-'!O10 | BF15: ='001 B-'!O10 | BG15: ='001 B-'!O10 | BH15: ='001 B-'!O10 | BI15: ='001 B-'!O10 | BJ15: ='001 B-'!O10 | BK15: ='001 B-'!O10 | BL15: ='001 B-'!O10 | BM15: ='001 B-'!O10 | BN15: ='001 B-'!O10 | BO15: ='001 B-'!O10 | BP15: ='001 B-'!O10 | BQ15: ='001 B-'!O10 | BR15: ='001 B-'!O10 | BS15: ='001 B-'!O10 | BT15: ='001 B-'!O10 | BU15: ='001 B-'!O10 | BV15: ='001 B-'!O10 | BW15: ='001 B-'!O10 | BX15: ='001 B-'!O10 | BY15: ='001 B-'!O10 | BZ15: ='001 B-'!O10 | CA15: ='001 B-'!O10 | CB15: ='001 B-'!O10 | CC15: ='001 B-'!O10 | CD15: ='001 B-'!O10 | CE15: ='001 B-'!O10 | CF15: ='001 B-'!O10 | CG15: ='001 B-'!O10 | CH15: ='001 B-'!O10 | CI15: ='001 B-'!O10 | CJ15: ='001 B-'!O10 | CK15: ='001 B-'!O10 | CL15: ='001 B-'!O10 | CM15: ='001 B-'!O10 | CN15: ='001 B-'!O10 | CO15: ='001 B-'!O10 | CP15: ='001 B-'!O10 | CQ15: ='001 B-'!O10 | CR15: ='001 B-'!O10 | CS15: ='001 B-'!O10 | CT15: ='001 B-'!O10 | CU15: ='001 B-'!O10 | CV15: ='001 B-'!O10 | CW15: ='001 B-'!O10 | CX15: ='001 B-'!O10 | CY15: ='001 B-'!O10 | CZ15: ='001 B-'!O10 | DA15: ='001 B-'!O10 | DB15: ='001 B-'!O10 | DC15: ='001 B-'!O10 | DD15: ='001 B-'!O10 | DE15: ='001 B-'!O10 | DF15: ='001 B-'!O10 | DG15: ='001 B-'!O10 | DH15: ='001 B-'!O10 | DI15: ='001 B-'!O10 | DJ15: ='001 B-'!O10 | DK15: ='001 B-'!O10
B16: walon | C16: Walloon | D16: ='001 B-'!P10 -> 2 | E16: ='002 B-'!P10 -> 2 | F16: ='003 T-'!P10 -> 5 | G16: ='003 T-'!P10 -> 5 | H16: ='003 T-'!P10 -> 5 | I16: ='004 T-'!P10 -> 5 | J16: ='004 T-'!P10 -> 5 | K16: ='005 D-'!P10 -> 6 | L16: ='005 D-'!P10 -> 6 | M16: ='005 D-'!P10 -> 6 | N16: ='006 D-'!P10 -> 6 | O16: ='006 D-'!P10 -> 6 | P16: ='007 C-'!P10 -> 48 | Q16: ='007 C-'!P10 -> 48 | R16: ='008 C-'!P10 -> 56 | S16: ='009 C-'!P10 -> 19 | T16: ='009 C-'!P10 -> 19 | U16: ='001 B-'!P10 | V16: ='001 B-'!P10 | W16: ='001 B-'!P10 | X16: ='001 B-'!P10 | Y16: ='001 B-'!P10 | Z16: ='001 B-'!P10 | AA16: ='001 B-'!P10 | AB16: ='001 B-'!P10 | AC16: ='001 B-'!P10 | AD16: ='001 B-'!P10 | AE16: ='001 B-'!P10 | AF16: ='001 B-'!P10 | AG16: ='001 B-'!P10 | AH16: ='001 B-'!P10 | AI16: ='001 B-'!P10 | AJ16: ='001 B-'!P10 | AK16: ='001 B-'!P10 | AL16: ='001 B-'!P10 | AM16: ='001 B-'!P10 | AN16: ='001 B-'!P10 | AO16: ='001 B-'!P10 | AP16: ='001 B-'!P10 | AQ16: ='001 B-'!P10 | AR16: ='001 B-'!P10 | AS16: ='001 B-'!P10 | AT16: ='001 B-'!P10 | AU16: ='001 B-'!P10 | AV16: ='001 B-'!P10 | AW16: ='001 B-'!P10 | AX16: ='001 B-'!P10 | AY16: ='001 B-'!P10 | AZ16: ='001 B-'!P10 | BA16: ='001 B-'!P10 | BB16: ='001 B-'!P10 | BC16: ='001 B-'!P10 | BD16: ='001 B-'!P10 | BE16: ='001 B-'!P10 | BF16: ='001 B-'!P10 | BG16: ='001 B-'!P10 | BH16: ='001 B-'!P10 | BI16: ='001 B-'!P10 | BJ16: ='001 B-'!P10 | BK16: ='001 B-'!P10 | BL16: ='001 B-'!P10 | BM16: ='001 B-'!P10 | BN16: ='001 B-'!P10 | BO16: ='001 B-'!P10 | BP16: ='001 B-'!P10 | BQ16: ='001 B-'!P10 | BR16: ='001 B-'!P10 | BS16: ='001 B-'!P10 | BT16: ='001 B-'!P10 | BU16: ='001 B-'!P10 | BV16: ='001 B-'!P10 | BW16: ='001 B-'!P10 | BX16: ='001 B-'!P10 | BY16: ='001 B-'!P10 | BZ16: ='001 B-'!P10 | CA16: ='001 B-'!P10 | CB16: ='001 B-'!P10 | CC16: ='001 B-'!P10 | CD16: ='001 B-'!P10 | CE16: ='001 B-'!P10 | CF16: ='001 B-'!P10 | CG16: ='001 B-'!P10 | CH16: ='001 B-'!P10 | CI16: ='001 B-'!P10 | CJ16: ='001 B-'!P10 | CK16: ='001 B-'!P10 | CL16: ='001 B-'!P10 | CM16: ='001 B-'!P10 | CN16: ='001 B-'!P10 | CO16: ='001 B-'!P10 | CP16: ='001 B-'!P10 | CQ16: ='001 B-'!P10 | CR16: ='001 B-'!P10 | CS16: ='001 B-'!P10 | CT16: ='001 B-'!P10 | CU16: ='001 B-'!P10 | CV16: ='001 B-'!P10 | CW16: ='001 B-'!P10 | CX16: ='001 B-'!P10 | CY16: ='001 B-'!P10 | CZ16: ='001 B-'!P10 | DA16: ='001 B-'!P10 | DB16: ='001 B-'!P10 | DC16: ='001 B-'!P10 | DD16: ='001 B-'!P10 | DE16: ='001 B-'!P10 | DF16: ='001 B-'!P10 | DG16: ='001 B-'!P10 | DH16: ='001 B-'!P10 | DI16: ='001 B-'!P10 | DJ16: ='001 B-'!P10 | DK16: ='001 B-'!P10
A17: * | B17: français européen | C17: French | D17: ='001 B-'!Q10 -> 2 | E17: ='002 B-'!Q10 -> 2 | F17: ='003 T-'!Q10 -> 5 | G17: ='003 T-'!Q10 -> 5 | H17: ='003 T-'!Q10 -> 5 | I17: ='004 T-'!Q10 -> 5 | J17: ='004 T-'!Q10 -> 5 | K17: ='005 D-'!Q10 -> 6 | L17: ='005 D-'!Q10 -> 6 | M17: ='005 D-'!Q10 -> 6 | N17: ='006 D-'!Q10 -> 6 | O17: ='006 D-'!Q10 -> 6 | P17: ='007 C-'!Q10 -> 48 | Q17: ='007 C-'!Q10 -> 48 | R17: ='008 C-'!Q10 -> 56 | S17: ='009 C-'!Q10 -> 19 | T17: ='009 C-'!Q10 -> 19 | U17: ='001 B-'!Q10 | V17: ='001 B-'!Q10 | W17: ='001 B-'!Q10 | X17: ='001 B-'!Q10 | Y17: ='001 B-'!Q10 | Z17: ='001 B-'!Q10 | AA17: ='001 B-'!Q10 | AB17: ='001 B-'!Q10 | AC17: ='001 B-'!Q10 | AD17: ='001 B-'!Q10 | AE17: ='001 B-'!Q10 | AF17: ='001 B-'!Q10 | AG17: ='001 B-'!Q10 | AH17: ='001 B-'!Q10 | AI17: ='001 B-'!Q10 | AJ17: ='001 B-'!Q10 | AK17: ='001 B-'!Q10 | AL17: ='001 B-'!Q10 | AM17: ='001 B-'!Q10 | AN17: ='001 B-'!Q10 | AO17: ='001 B-'!Q10 | AP17: ='001 B-'!Q10 | AQ17: ='001 B-'!Q10 | AR17: ='001 B-'!Q10 | AS17: ='001 B-'!Q10 | AT17: ='001 B-'!Q10 | AU17: ='001 B-'!Q10 | AV17: ='001 B-'!Q10 | AW17: ='001 B-'!Q10 | AX17: ='001 B-'!Q10 | AY17: ='001 B-'!Q10 | AZ17: ='001 B-'!Q10 | BA17: ='001 B-'!Q10 | BB17: ='001 B-'!Q10 | BC17: ='001 B-'!Q10 | BD17: ='001 B-'!Q10 | BE17: ='001 B-'!Q10 | BF17: ='001 B-'!Q10 | BG17: ='001 B-'!Q10 | BH17: ='001 B-'!Q10 | BI17: ='001 B-'!Q10 | BJ17: ='001 B-'!Q10 | BK17: ='001 B-'!Q10 | BL17: ='001 B-'!Q10 | BM17: ='001 B-'!Q10 | BN17: ='001 B-'!Q10 | BO17: ='001 B-'!Q10 | BP17: ='001 B-'!Q10 | BQ17: ='001 B-'!Q10 | BR17: ='001 B-'!Q10 | BS17: ='001 B-'!Q10 | BT17: ='001 B-'!Q10 | BU17: ='001 B-'!Q10 | BV17: ='001 B-'!Q10 | BW17: ='001 B-'!Q10 | BX17: ='001 B-'!Q10 | BY17: ='001 B-'!Q10 | BZ17: ='001 B-'!Q10 | CA17: ='001 B-'!Q10 | CB17: ='001 B-'!Q10 | CC17: ='001 B-'!Q10 | CD17: ='001 B-'!Q10 | CE17: ='001 B-'!Q10 | CF17: ='001 B-'!Q10 | CG17: ='001 B-'!Q10 | CH17: ='001 B-'!Q10 | CI17: ='001 B-'!Q10 | CJ17: ='001 B-'!Q10 | CK17: ='001 B-'!Q10 | CL17: ='001 B-'!Q10 | CM17: ='001 B-'!Q10 | CN17: ='001 B-'!Q10 | CO17: ='001 B-'!Q10 | CP17: ='001 B-'!Q10 | CQ17: ='001 B-'!Q10 | CR17: ='001 B-'!Q10 | CS17: ='001 B-'!Q10 | CT17: ='001 B-'!Q10 | CU17: ='001 B-'!Q10 | CV17: ='001 B-'!Q10 | CW17: ='001 B-'!Q10 | CX17: ='001 B-'!Q10 | CY17: ='001 B-'!Q10 | CZ17: ='001 B-'!Q10 | DA17: ='001 B-'!Q10 | DB17: ='001 B-'!Q10 | DC17: ='001 B-'!Q10 | DD17: ='001 B-'!Q10 | DE17: ='001 B-'!Q10 | DF17: ='001 B-'!Q10 | DG17: ='001 B-'!Q10 | DH17: ='001 B-'!Q10 | DI17: ='001 B-'!Q10 | DJ17: ='001 B-'!Q10 | DK17: ='001 B-'!Q10
B18: français québécois | C18: Québécois French | D18: ='001 B-'!R10 -> 2 | E18: ='002 B-'!R10 -> 2 | F18: ='003 T-'!R10 -> 5 | G18: ='003 T-'!R10 -> 5 | H18: ='003 T-'!AN10 -> 26 | I18: ='004 T-'!R10 -> 5 | J18: ='004 T-'!AJ10 -> 26 | K18: ='005 D-'!R10 -> 6 | L18: ='005 D-'!R10 -> 6 | M18: ='005 D-'!AN10 -> 27 | N18: ='006 D-'!R10 -> 6 | O18: ='006 D-'!AJ10 -> 27 | P18: ='007 C-'!R10 -> 48 | Q18: ='007 C-'!R10 -> 48 | R18: ='008 C-'!R10 -> 34 | S18: ='009 C-'!R10 -> 19 | T18: ='009 C-'!R10 -> 19 | U18: ='001 B-'!R10 | V18: ='001 B-'!R10 | W18: ='001 B-'!R10 | X18: ='001 B-'!R10 | Y18: ='001 B-'!R10 | Z18: ='001 B-'!R10 | AA18: ='001 B-'!R10 | AB18: ='001 B-'!R10 | AC18: ='001 B-'!R10 | AD18: ='001 B-'!R10 | AE18: ='001 B-'!R10 | AF18: ='001 B-'!R10 | AG18: ='001 B-'!R10 | AH18: ='001 B-'!R10 | AI18: ='001 B-'!R10 | AJ18: ='001 B-'!R10 | AK18: ='001 B-'!R10 | AL18: ='001 B-'!R10 | AM18: ='001 B-'!R10 | AN18: ='001 B-'!R10 | AO18: ='001 B-'!R10 | AP18: ='001 B-'!R10 | AQ18: ='001 B-'!R10 | AR18: ='001 B-'!R10 | AS18: ='001 B-'!R10 | AT18: ='001 B-'!R10 | AU18: ='001 B-'!R10 | AV18: ='001 B-'!R10 | AW18: ='001 B-'!R10 | AX18: ='001 B-'!R10 | AY18: ='001 B-'!R10 | AZ18: ='001 B-'!R10 | BA18: ='001 B-'!R10 | BB18: ='001 B-'!R10 | BC18: ='001 B-'!R10 | BD18: ='001 B-'!R10 | BE18: ='001 B-'!R10 | BF18: ='001 B-'!R10 | BG18: ='001 B-'!R10 | BH18: ='001 B-'!R10 | BI18: ='001 B-'!R10 | BJ18: ='001 B-'!R10 | BK18: ='001 B-'!R10 | BL18: ='001 B-'!R10 | BM18: ='001 B-'!R10 | BN18: ='001 B-'!R10 | BO18: ='001 B-'!R10 | BP18: ='001 B-'!R10 | BQ18: ='001 B-'!R10 | BR18: ='001 B-'!R10 | BS18: ='001 B-'!R10 | BT18: ='001 B-'!R10 | BU18: ='001 B-'!R10 | BV18: ='001 B-'!R10 | BW18: ='001 B-'!R10 | BX18: ='001 B-'!R10 | BY18: ='001 B-'!R10 | BZ18: ='001 B-'!R10 | CA18: ='001 B-'!R10 | CB18: ='001 B-'!R10 | CC18: ='001 B-'!R10 | CD18: ='001 B-'!R10 | CE18: ='001 B-'!R10 | CF18: ='001 B-'!R10 | CG18: ='001 B-'!R10 | CH18: ='001 B-'!R10 | CI18: ='001 B-'!R10 | CJ18: ='001 B-'!R10 | CK18: ='001 B-'!R10 | CL18: ='001 B-'!R10 | CM18: ='001 B-'!R10 | CN18: ='001 B-'!R10 | CO18: ='001 B-'!R10 | CP18: ='001 B-'!R10 | CQ18: ='001 B-'!R10 | CR18: ='001 B-'!R10 | CS18: ='001 B-'!R10 | CT18: ='001 B-'!R10 | CU18: ='001 B-'!R10 | CV18: ='001 B-'!R10 | CW18: ='001 B-'!R10 | CX18: ='001 B-'!R10 | CY18: ='001 B-'!R10 | CZ18: ='001 B-'!R10 | DA18: ='001 B-'!R10 | DB18: ='001 B-'!R10 | DC18: ='001 B-'!R10 | DD18: ='001 B-'!R10 | DE18: ='001 B-'!R10 | DF18: ='001 B-'!R10 | DG18: ='001 B-'!R10 | DH18: ='001 B-'!R10 | DI18: ='001 B-'!R10 | DJ18: ='001 B-'!R10 | DK18: ='001 B-'!R10
A19: * | B19: arpetan | C19: Arpitan | D19: ='001 B-'!S10 -> 2 | E19: ='002 B-'!S10 -> 2 | F19: ='003 T-'!S10 -> 5 | G19: ='003 T-'!S10 -> 5 | H19: ='003 T-'!S10 -> 5 | I19: ='004 T-'!S10 -> 5 | J19: ='004 T-'!S10 -> 5 | K19: ='005 D-'!S10 -> 6 | L19: ='005 D-'!S10 -> 6 | M19: ='005 D-'!S10 -> 6 | N19: ='006 D-'!S10 -> 6 | O19: ='006 D-'!S10 -> 6 | P19: ='007 C-'!S10 -> 48 | Q19: ='007 C-'!S10 -> 48 | R19: ='008 C-'!S10 -> 106 | S19: ='009 C-'!S10 -> 19 | T19: ='009 C-'!S10 -> 19 | U19: ='001 B-'!S10 | V19: ='001 B-'!S10 | W19: ='001 B-'!S10 | X19: ='001 B-'!S10 | Y19: ='001 B-'!S10 | Z19: ='001 B-'!S10 | AA19: ='001 B-'!S10 | AB19: ='001 B-'!S10 | AC19: ='001 B-'!S10 | AD19: ='001 B-'!S10 | AE19: ='001 B-'!S10 | AF19: ='001 B-'!S10 | AG19: ='001 B-'!S10 | AH19: ='001 B-'!S10 | AI19: ='001 B-'!S10 | AJ19: ='001 B-'!S10 | AK19: ='001 B-'!S10 | AL19: ='001 B-'!S10 | AM19: ='001 B-'!S10 | AN19: ='001 B-'!S10 | AO19: ='001 B-'!S10 | AP19: ='001 B-'!S10 | AQ19: ='001 B-'!S10 | AR19: ='001 B-'!S10 | AS19: ='001 B-'!S10 | AT19: ='001 B-'!S10 | AU19: ='001 B-'!S10 | AV19: ='001 B-'!S10 | AW19: ='001 B-'!S10 | AX19: ='001 B-'!S10 | AY19: ='001 B-'!S10 | AZ19: ='001 B-'!S10 | BA19: ='001 B-'!S10 | BB19: ='001 B-'!S10 | BC19: ='001 B-'!S10 | BD19: ='001 B-'!S10 | BE19: ='001 B-'!S10 | BF19: ='001 B-'!S10 | BG19: ='001 B-'!S10 | BH19: ='001 B-'!S10 | BI19: ='001 B-'!S10 | BJ19: ='001 B-'!S10 | BK19: ='001 B-'!S10 | BL19: ='001 B-'!S10 | BM19: ='001 B-'!S10 | BN19: ='001 B-'!S10 | BO19: ='001 B-'!S10 | BP19: ='001 B-'!S10 | BQ19: ='001 B-'!S10 | BR19: ='001 B-'!S10 | BS19: ='001 B-'!S10 | BT19: ='001 B-'!S10 | BU19: ='001 B-'!S10 | BV19: ='001 B-'!S10 | BW19: ='001 B-'!S10 | BX19: ='001 B-'!S10 | BY19: ='001 B-'!S10 | BZ19: ='001 B-'!S10 | CA19: ='001 B-'!S10 | CB19: ='001 B-'!S10 | CC19: ='001 B-'!S10 | CD19: ='001 B-'!S10 | CE19: ='001 B-'!S10 | CF19: ='001 B-'!S10 | CG19: ='001 B-'!S10 | CH19: ='001 B-'!S10 | CI19: ='001 B-'!S10 | CJ19: ='001 B-'!S10 | CK19: ='001 B-'!S10 | CL19: ='001 B-'!S10 | CM19: ='001 B-'!S10 | CN19: ='001 B-'!S10 | CO19: ='001 B-'!S10 | CP19: ='001 B-'!S10 | CQ19: ='001 B-'!S10 | CR19: ='001 B-'!S10 | CS19: ='001 B-'!S10 | CT19: ='001 B-'!S10 | CU19: ='001 B-'!S10 | CV19: ='001 B-'!S10 | CW19: ='001 B-'!S10 | CX19: ='001 B-'!S10 | CY19: ='001 B-'!S10 | CZ19: ='001 B-'!S10 | DA19: ='001 B-'!S10 | DB19: ='001 B-'!S10 | DC19: ='001 B-'!S10 | DD19: ='001 B-'!S10 | DE19: ='001 B-'!S10 | DF19: ='001 B-'!S10 | DG19: ='001 B-'!S10 | DH19: ='001 B-'!S10 | DI19: ='001 B-'!S10 | DJ19: ='001 B-'!S10 | DK19: ='001 B-'!S10
B20: lìgure | C20: Ligurian | D20: ='001 B-'!T10 -> 2 | E20: ='002 B-'!T10 -> 2 | F20: ='003 T-'!T10 -> 5 | G20: ='003 T-'!T10 -> 5 | H20: ='003 T-'!T10 -> 5 | I20: ='004 T-'!T10 -> 5 | J20: ='004 T-'!T10 -> 5 | K20: ='005 D-'!T10 -> 6 | L20: ='005 D-'!T10 -> 6 | M20: ='005 D-'!T10 -> 6 | N20: ='006 D-'!T10 -> 6 | O20: ='006 D-'!T10 -> 6 | P20: ='007 C-'!T10 -> 274 | Q20: ='007 C-'!T10 -> 274 | R20: ='008 C-'!T10 -> 19 | S20: ='009 C-'!T10 -> 19 | T20: ='009 C-'!T10 -> 19 | U20: ='001 B-'!T10 | V20: ='001 B-'!T10 | W20: ='001 B-'!T10 | X20: ='001 B-'!T10 | Y20: ='001 B-'!T10 | Z20: ='001 B-'!T10 | AA20: ='001 B-'!T10 | AB20: ='001 B-'!T10 | AC20: ='001 B-'!T10 | AD20: ='001 B-'!T10 | AE20: ='001 B-'!T10 | AF20: ='001 B-'!T10 | AG20: ='001 B-'!T10 | AH20: ='001 B-'!T10 | AI20: ='001 B-'!T10 | AJ20: ='001 B-'!T10 | AK20: ='001 B-'!T10 | AL20: ='001 B-'!T10 | AM20: ='001 B-'!T10 | AN20: ='001 B-'!T10 | AO20: ='001 B-'!T10 | AP20: ='001 B-'!T10 | AQ20: ='001 B-'!T10 | AR20: ='001 B-'!T10 | AS20: ='001 B-'!T10 | AT20: ='001 B-'!T10 | AU20: ='001 B-'!T10 | AV20: ='001 B-'!T10 | AW20: ='001 B-'!T10 | AX20: ='001 B-'!T10 | AY20: ='001 B-'!T10 | AZ20: ='001 B-'!T10 | BA20: ='001 B-'!T10 | BB20: ='001 B-'!T10 | BC20: ='001 B-'!T10 | BD20: ='001 B-'!T10 | BE20: ='001 B-'!T10 | BF20: ='001 B-'!T10 | BG20: ='001 B-'!T10 | BH20: ='001 B-'!T10 | BI20: ='001 B-'!T10 | BJ20: ='001 B-'!T10 | BK20: ='001 B-'!T10 | BL20: ='001 B-'!T10 | BM20: ='001 B-'!T10 | BN20: ='001 B-'!T10 | BO20: ='001 B-'!T10 | BP20: ='001 B-'!T10 | BQ20: ='001 B-'!T10 | BR20: ='001 B-'!T10 | BS20: ='001 B-'!T10 | BT20: ='001 B-'!T10 | BU20: ='001 B-'!T10 | BV20: ='001 B-'!T10 | BW20: ='001 B-'!T10 | BX20: ='001 B-'!T10 | BY20: ='001 B-'!T10 | BZ20: ='001 B-'!T10 | CA20: ='001 B-'!T10 | CB20: ='001 B-'!T10 | CC20: ='001 B-'!T10 | CD20: ='001 B-'!T10 | CE20: ='001 B-'!T10 | CF20: ='001 B-'!T10 | CG20: ='001 B-'!T10 | CH20: ='001 B-'!T10 | CI20: ='001 B-'!T10 | CJ20: ='001 B-'!T10 | CK20: ='001 B-'!T10 | CL20: ='001 B-'!T10 | CM20: ='001 B-'!T10 | CN20: ='001 B-'!T10 | CO20: ='001 B-'!T10 | CP20: ='001 B-'!T10 | CQ20: ='001 B-'!T10 | CR20: ='001 B-'!T10 | CS20: ='001 B-'!T10 | CT20: ='001 B-'!T10 | CU20: ='001 B-'!T10 | CV20: ='001 B-'!T10 | CW20: ='001 B-'!T10 | CX20: ='001 B-'!T10 | CY20: ='001 B-'!T10 | CZ20: ='001 B-'!T10 | DA20: ='001 B-'!T10 | DB20: ='001 B-'!T10 | DC20: ='001 B-'!T10 | DD20: ='001 B-'!T10 | DE20: ='001 B-'!T10 | DF20: ='001 B-'!T10 | DG20: ='001 B-'!T10 | DH20: ='001 B-'!T10 | DI20: ='001 B-'!T10 | DJ20: ='001 B-'!T10 | DK20: ='001 B-'!T10
A21: * | B21: lombard | C21: Lombard | D21: ='001 B-'!U10 -> 2 | E21: ='002 B-'!U10 -> 2 | F21: ='003 T-'!U10 -> 5 | G21: ='003 T-'!U10 -> 5 | H21: ='003 T-'!U10 -> 5 | I21: ='004 T-'!U10 -> 5 | J21: ='004 T-'!U10 -> 5 | K21: ='005 D-'!U10 -> 6 | L21: ='005 D-'!U10 -> 6 | M21: ='005 D-'!U10 -> 6 | N21: ='006 D-'!U10 -> 6 | O21: ='006 D-'!U10 -> 6 | P21: ='007 C-'!U10 -> 103 | Q21: ='007 C-'!U10 -> 103 | R21: ='008 C-'!U10 -> 19 | S21: ='009 C-'!U10 -> 19 | T21: ='009 C-'!U10 -> 19 | U21: ='001 B-'!U10 | V21: ='001 B-'!U10 | W21: ='001 B-'!U10 | X21: ='001 B-'!U10 | Y21: ='001 B-'!U10 | Z21: ='001 B-'!U10 | AA21: ='001 B-'!U10 | AB21: ='001 B-'!U10 | AC21: ='001 B-'!U10 | AD21: ='001 B-'!U10 | AE21: ='001 B-'!U10 | AF21: ='001 B-'!U10 | AG21: ='001 B-'!U10 | AH21: ='001 B-'!U10 | AI21: ='001 B-'!U10 | AJ21: ='001 B-'!U10 | AK21: ='001 B-'!U10 | AL21: ='001 B-'!U10 | AM21: ='001 B-'!U10 | AN21: ='001 B-'!U10 | AO21: ='001 B-'!U10 | AP21: ='001 B-'!U10 | AQ21: ='001 B-'!U10 | AR21: ='001 B-'!U10 | AS21: ='001 B-'!U10 | AT21: ='001 B-'!U10 | AU21: ='001 B-'!U10 | AV21: ='001 B-'!U10 | AW21: ='001 B-'!U10 | AX21: ='001 B-'!U10 | AY21: ='001 B-'!U10 | AZ21: ='001 B-'!U10 | BA21: ='001 B-'!U10 | BB21: ='001 B-'!U10 | BC21: ='001 B-'!U10 | BD21: ='001 B-'!U10 | BE21: ='001 B-'!U10 | BF21: ='001 B-'!U10 | BG21: ='001 B-'!U10 | BH21: ='001 B-'!U10 | BI21: ='001 B-'!U10 | BJ21: ='001 B-'!U10 | BK21: ='001 B-'!U10 | BL21: ='001 B-'!U10 | BM21: ='001 B-'!U10 | BN21: ='001 B-'!U10 | BO21: ='001 B-'!U10 | BP21: ='001 B-'!U10 | BQ21: ='001 B-'!U10 | BR21: ='001 B-'!U10 | BS21: ='001 B-'!U10 | BT21: ='001 B-'!U10 | BU21: ='001 B-'!U10 | BV21: ='001 B-'!U10 | BW21: ='001 B-'!U10 | BX21: ='001 B-'!U10 | BY21: ='001 B-'!U10 | BZ21: ='001 B-'!U10 | CA21: ='001 B-'!U10 | CB21: ='001 B-'!U10 | CC21: ='001 B-'!U10 | CD21: ='001 B-'!U10 | CE21: ='001 B-'!U10 | CF21: ='001 B-'!U10 | CG21: ='001 B-'!U10 | CH21: ='001 B-'!U10 | CI21: ='001 B-'!U10 | CJ21: ='001 B-'!U10 | CK21: ='001 B-'!U10 | CL21: ='001 B-'!U10 | CM21: ='001 B-'!U10 | CN21: ='001 B-'!U10 | CO21: ='001 B-'!U10 | CP21: ='001 B-'!U10 | CQ21: ='001 B-'!U10 | CR21: ='001 B-'!U10 | CS21: ='001 B-'!U10 | CT21: ='001 B-'!U10 | CU21: ='001 B-'!U10 | CV21: ='001 B-'!U10 | CW21: ='001 B-'!U10 | CX21: ='001 B-'!U10 | CY21: ='001 B-'!U10 | CZ21: ='001 B-'!U10 | DA21: ='001 B-'!U10 | DB21: ='001 B-'!U10 | DC21: ='001 B-'!U10 | DD21: ='001 B-'!U10 | DE21: ='001 B-'!U10 | DF21: ='001 B-'!U10 | DG21: ='001 B-'!U10 | DH21: ='001 B-'!U10 | DI21: ='001 B-'!U10 | DJ21: ='001 B-'!U10 | DK21: ='001 B-'!U10
B22: rumantsch | C22: Romansh | D22: ='001 B-'!V10 -> 2 | E22: ='002 B-'!V10 -> 2 | F22: ='003 T-'!V10 -> 5 | G22: ='003 T-'!V10 -> 5 | H22: ='003 T-'!V10 -> 5 | I22: ='004 T-'!V10 -> 5 | J22: ='004 T-'!V10 -> 5 | K22: ='005 D-'!V10 -> 6 | L22: ='005 D-'!V10 -> 6 | M22: ='005 D-'!V10 -> 6 | N22: ='006 D-'!V10 -> 6 | O22: ='006 D-'!V10 -> 6 | P22: ='007 C-'!V10 -> 34 | Q22: ='007 C-'!V10 -> 34 | R22: ='008 C-'!V10 -> 150 | S22: ='009 C-'!V10 -> 0 | T22: ='009 C-'!V10 -> 0 | U22: ='001 B-'!V10 | V22: ='001 B-'!V10 | W22: ='001 B-'!V10 | X22: ='001 B-'!V10 | Y22: ='001 B-'!V10 | Z22: ='001 B-'!V10 | AA22: ='001 B-'!V10 | AB22: ='001 B-'!V10 | AC22: ='001 B-'!V10 | AD22: ='001 B-'!V10 | AE22: ='001 B-'!V10 | AF22: ='001 B-'!V10 | AG22: ='001 B-'!V10 | AH22: ='001 B-'!V10 | AI22: ='001 B-'!V10 | AJ22: ='001 B-'!V10 | AK22: ='001 B-'!V10 | AL22: ='001 B-'!V10 | AM22: ='001 B-'!V10 | AN22: ='001 B-'!V10 | AO22: ='001 B-'!V10 | AP22: ='001 B-'!V10 | AQ22: ='001 B-'!V10 | AR22: ='001 B-'!V10 | AS22: ='001 B-'!V10 | AT22: ='001 B-'!V10 | AU22: ='001 B-'!V10 | AV22: ='001 B-'!V10 | AW22: ='001 B-'!V10 | AX22: ='001 B-'!V10 | AY22: ='001 B-'!V10 | AZ22: ='001 B-'!V10 | BA22: ='001 B-'!V10 | BB22: ='001 B-'!V10 | BC22: ='001 B-'!V10 | BD22: ='001 B-'!V10 | BE22: ='001 B-'!V10 | BF22: ='001 B-'!V10 | BG22: ='001 B-'!V10 | BH22: ='001 B-'!V10 | BI22: ='001 B-'!V10 | BJ22: ='001 B-'!V10 | BK22: ='001 B-'!V10 | BL22: ='001 B-'!V10 | BM22: ='001 B-'!V10 | BN22: ='001 B-'!V10 | BO22: ='001 B-'!V10 | BP22: ='001 B-'!V10 | BQ22: ='001 B-'!V10 | BR22: ='001 B-'!V10 | BS22: ='001 B-'!V10 | BT22: ='001 B-'!V10 | BU22: ='001 B-'!V10 | BV22: ='001 B-'!V10 | BW22: ='001 B-'!V10 | BX22: ='001 B-'!V10 | BY22: ='001 B-'!V10 | BZ22: ='001 B-'!V10 | CA22: ='001 B-'!V10 | CB22: ='001 B-'!V10 | CC22: ='001 B-'!V10 | CD22: ='001 B-'!V10 | CE22: ='001 B-'!V10 | CF22: ='001 B-'!V10 | CG22: ='001 B-'!V10 | CH22: ='001 B-'!V10 | CI22: ='001 B-'!V10 | CJ22: ='001 B-'!V10 | CK22: ='001 B-'!V10 | CL22: ='001 B-'!V10 | CM22: ='001 B-'!V10 | CN22: ='001 B-'!V10 | CO22: ='001 B-'!V10 | CP22: ='001 B-'!V10 | CQ22: ='001 B-'!V10 | CR22: ='001 B-'!V10 | CS22: ='001 B-'!V10 | CT22: ='001 B-'!V10 | CU22: ='001 B-'!V10 | CV22: ='001 B-'!V10 | CW22: ='001 B-'!V10 | CX22: ='001 B-'!V10 | CY22: ='001 B-'!V10 | CZ22: ='001 B-'!V10 | DA22: ='001 B-'!V10 | DB22: ='001 B-'!V10 | DC22: ='001 B-'!V10 | DD22: ='001 B-'!V10 | DE22: ='001 B-'!V10 | DF22: ='001 B-'!V10 | DG22: ='001 B-'!V10 | DH22: ='001 B-'!V10 | DI22: ='001 B-'!V10 | DJ22: ='001 B-'!V10 | DK22: ='001 B-'!V10
B23: furlan | C23: Friulian | D23: ='001 B-'!W10 -> 2 | E23: ='002 B-'!W10 -> 2 | F23: ='003 T-'!W10 -> 5 | G23: ='003 T-'!W10 -> 5 | H23: ='003 T-'!W10 -> 5 | I23: ='004 T-'!W10 -> 5 | J23: ='004 T-'!W10 -> 5 | K23: ='005 D-'!W10 -> 6 | L23: ='005 D-'!W10 -> 6 | M23: ='005 D-'!W10 -> 6 | N23: ='006 D-'!W10 -> 6 | O23: ='006 D-'!W10 -> 6 | P23: ='007 C-'!W10 -> 0 | Q23: ='007 C-'!W10 -> 0 | R23: ='008 C-'!W10 -> 152 | S23: ='009 C-'!W10 -> 0 | T23: ='009 C-'!W10 -> 0 | U23: ='001 B-'!W10 | V23: ='001 B-'!W10 | W23: ='001 B-'!W10 | X23: ='001 B-'!W10 | Y23: ='001 B-'!W10 | Z23: ='001 B-'!W10 | AA23: ='001 B-'!W10 | AB23: ='001 B-'!W10 | AC23: ='001 B-'!W10 | AD23: ='001 B-'!W10 | AE23: ='001 B-'!W10 | AF23: ='001 B-'!W10 | AG23: ='001 B-'!W10 | AH23: ='001 B-'!W10 | AI23: ='001 B-'!W10 | AJ23: ='001 B-'!W10 | AK23: ='001 B-'!W10 | AL23: ='001 B-'!W10 | AM23: ='001 B-'!W10 | AN23: ='001 B-'!W10 | AO23: ='001 B-'!W10 | AP23: ='001 B-'!W10 | AQ23: ='001 B-'!W10 | AR23: ='001 B-'!W10 | AS23: ='001 B-'!W10 | AT23: ='001 B-'!W10 | AU23: ='001 B-'!W10 | AV23: ='001 B-'!W10 | AW23: ='001 B-'!W10 | AX23: ='001 B-'!W10 | AY23: ='001 B-'!W10 | AZ23: ='001 B-'!W10 | BA23: ='001 B-'!W10 | BB23: ='001 B-'!W10 | BC23: ='001 B-'!W10 | BD23: ='001 B-'!W10 | BE23: ='001 B-'!W10 | BF23: ='001 B-'!W10 | BG23: ='001 B-'!W10 | BH23: ='001 B-'!W10 | BI23: ='001 B-'!W10 | BJ23: ='001 B-'!W10 | BK23: ='001 B-'!W10 | BL23: ='001 B-'!W10 | BM23: ='001 B-'!W10 | BN23: ='001 B-'!W10 | BO23: ='001 B-'!W10 | BP23: ='001 B-'!W10 | BQ23: ='001 B-'!W10 | BR23: ='001 B-'!W10 | BS23: ='001 B-'!W10 | BT23: ='001 B-'!W10 | BU23: ='001 B-'!W10 | BV23: ='001 B-'!W10 | BW23: ='001 B-'!W10 | BX23: ='001 B-'!W10 | BY23: ='001 B-'!W10 | BZ23: ='001 B-'!W10 | CA23: ='001 B-'!W10 | CB23: ='001 B-'!W10 | CC23: ='001 B-'!W10 | CD23: ='001 B-'!W10 | CE23: ='001 B-'!W10 | CF23: ='001 B-'!W10 | CG23: ='001 B-'!W10 | CH23: ='001 B-'!W10 | CI23: ='001 B-'!W10 | CJ23: ='001 B-'!W10 | CK23: ='001 B-'!W10 | CL23: ='001 B-'!W10 | CM23: ='001 B-'!W10 | CN23: ='001 B-'!W10 | CO23: ='001 B-'!W10 | CP23: ='001 B-'!W10 | CQ23: ='001 B-'!W10 | CR23: ='001 B-'!W10 | CS23: ='001 B-'!W10 | CT23: ='001 B-'!W10 | CU23: ='001 B-'!W10 | CV23: ='001 B-'!W10 | CW23: ='001 B-'!W10 | CX23: ='001 B-'!W10 | CY23: ='001 B-'!W10 | CZ23: ='001 B-'!W10 | DA23: ='001 B-'!W10 | DB23: ='001 B-'!W10 | DC23: ='001 B-'!W10 | DD23: ='001 B-'!W10 | DE23: ='001 B-'!W10 | DF23: ='001 B-'!W10 | DG23: ='001 B-'!W10 | DH23: ='001 B-'!W10 | DI23: ='001 B-'!W10 | DJ23: ='001 B-'!W10 | DK23: ='001 B-'!W10
B24: sardu logudoresu | C24: Logudorese Sardinian | D24: ='001 B-'!X10 -> 273 | E24: ='002 B-'!X10 -> 273 | F24: ='003 T-'!X10 -> 5 | G24: ='003 T-'!X10 -> 5 | H24: ='003 T-'!X10 -> 5 | I24: ='004 T-'!X10 -> 5 | J24: ='004 T-'!X10 -> 5 | K24: ='005 D-'!X10 -> 6 | L24: ='005 D-'!X10 -> 6 | M24: ='005 D-'!X10 -> 6 | N24: ='006 D-'!X10 -> 6 | O24: ='006 D-'!X10 -> 6 | P24: ='007 C-'!X10 -> 19 | Q24: ='007 C-'!X10 -> 19 | R24: ='008 C-'!X10 -> 19 | S24: ='009 C-'!X10 -> 19 | T24: ='009 C-'!X10 -> 19 | U24: ='001 B-'!X10 | V24: ='001 B-'!X10 | W24: ='001 B-'!X10 | X24: ='001 B-'!X10 | Y24: ='001 B-'!X10 | Z24: ='001 B-'!X10 | AA24: ='001 B-'!X10 | AB24: ='001 B-'!X10 | AC24: ='001 B-'!X10 | AD24: ='001 B-'!X10 | AE24: ='001 B-'!X10 | AF24: ='001 B-'!X10 | AG24: ='001 B-'!X10 | AH24: ='001 B-'!X10 | AI24: ='001 B-'!X10 | AJ24: ='001 B-'!X10 | AK24: ='001 B-'!X10 | AL24: ='001 B-'!X10 | AM24: ='001 B-'!X10 | AN24: ='001 B-'!X10 | AO24: ='001 B-'!X10 | AP24: ='001 B-'!X10 | AQ24: ='001 B-'!X10 | AR24: ='001 B-'!X10 | AS24: ='001 B-'!X10 | AT24: ='001 B-'!X10 | AU24: ='001 B-'!X10 | AV24: ='001 B-'!X10 | AW24: ='001 B-'!X10 | AX24: ='001 B-'!X10 | AY24: ='001 B-'!X10 | AZ24: ='001 B-'!X10 | BA24: ='001 B-'!X10 | BB24: ='001 B-'!X10 | BC24: ='001 B-'!X10 | BD24: ='001 B-'!X10 | BE24: ='001 B-'!X10 | BF24: ='001 B-'!X10 | BG24: ='001 B-'!X10 | BH24: ='001 B-'!X10 | BI24: ='001 B-'!X10 | BJ24: ='001 B-'!X10 | BK24: ='001 B-'!X10 | BL24: ='001 B-'!X10 | BM24: ='001 B-'!X10 | BN24: ='001 B-'!X10 | BO24: ='001 B-'!X10 | BP24: ='001 B-'!X10 | BQ24: ='001 B-'!X10 | BR24: ='001 B-'!X10 | BS24: ='001 B-'!X10 | BT24: ='001 B-'!X10 | BU24: ='001 B-'!X10 | BV24: ='001 B-'!X10 | BW24: ='001 B-'!X10 | BX24: ='001 B-'!X10 | BY24: ='001 B-'!X10 | BZ24: ='001 B-'!X10 | CA24: ='001 B-'!X10 | CB24: ='001 B-'!X10 | CC24: ='001 B-'!X10 | CD24: ='001 B-'!X10 | CE24: ='001 B-'!X10 | CF24: ='001 B-'!X10 | CG24: ='001 B-'!X10 | CH24: ='001 B-'!X10 | CI24: ='001 B-'!X10 | CJ24: ='001 B-'!X10 | CK24: ='001 B-'!X10 | CL24: ='001 B-'!X10 | CM24: ='001 B-'!X10 | CN24: ='001 B-'!X10 | CO24: ='001 B-'!X10 | CP24: ='001 B-'!X10 | CQ24: ='001 B-'!X10 | CR24: ='001 B-'!X10 | CS24: ='001 B-'!X10 | CT24: ='001 B-'!X10 | CU24: ='001 B-'!X10 | CV24: ='001 B-'!X10 | CW24: ='001 B-'!X10 | CX24: ='001 B-'!X10 | CY24: ='001 B-'!X10 | CZ24: ='001 B-'!X10 | DA24: ='001 B-'!X10 | DB24: ='001 B-'!X10 | DC24: ='001 B-'!X10 | DD24: ='001 B-'!X10 | DE24: ='001 B-'!X10 | DF24: ='001 B-'!X10 | DG24: ='001 B-'!X10 | DH24: ='001 B-'!X10 | DI24: ='001 B-'!X10 | DJ24: ='001 B-'!X10 | DK24: ='001 B-'!X10
